Workbook
Name Slicer_Category: #N/A
Name Slicer_Stock_Status: #N/A
Name Slicer_Weight_Category: #N/A
Name Slicer_Discount_Band: #N/A

Sheet Zepto Slicer Dashboard
B1: Zepto Inventory - Pivot & Slicer Dashboard
B2: Click the slicers on the left (Ctrl+click for multi-select). Every pivot table and chart on this page updates. Built on real PivotTables.

Sheet Zepto Dashboard
B1: Zepto Inventory - Interactive Dashboard
B2: Pick a Group by, Value field, Aggregation, Split and filters in the yellow cells - every chart and KPI updates. Source: Zepto_v1__1_.csv (cleaned as in your SQL).
B4: CONTROLS | F4: SKUs (FILTERED) | I4: OUT-OF-STOCK SHARE | L4: AVERAGE DISCOUNT % | O4: ESTIMATED REVENUE (Rs)
B5: Group by (X axis) | C5: Category | F5: =COUNTIFS(Zepto_Data!$A$2:$A$3732,ZP_Engine!$B$11,Zepto_Data!$L$2:$L$3732,ZP_Engine!$B$12,Zepto_Data!$K$2:$K$3732,ZP_Engine!$B$13,Zepto_Data!$M$2:$M$3732,ZP_Engine!$B$14) -> 3731 | I5: =IFERROR(COUNTIFS(Zepto_Data!$L$2:$L$3732,"Out of stock",Zepto_Data!$A$2:$A$3732,ZP_Engine!$B$11,Zepto_Data!$L$2:$L$3732,ZP_Engine!$B$12,Zepto_Data!$K$2:$K$3732,ZP_Engine!$B$13,Zepto_Data!$M$2:$M$3732,ZP_Engine!$B$14)/COUNTIFS(Zepto_Data!$A$2:$A$3732,ZP_Engine!$B$11,Zepto_Data!$L$2:$L$3732,ZP_Engine!$B$12,Zepto_Data!$K$2:$K$3732,ZP_Engine!$B$13,Zepto_Data!$M$2:$M$3732,ZP_Engine!$B$14),0) -> 0.12141517 | L5: =IFERROR(AVERAGEIFS(Zepto_Data!$D$2:$D$3732,Zepto_Data!$A$2:$A$3732,ZP_Engine!$B$11,Zepto_Data!$L$2:$L$3732,ZP_Engine!$B$12,Zepto_Data!$K$2:$K$3732,ZP_Engine!$B$13,Zepto_Data!$M$2:$M$3732,ZP_Engine!$B$14),0) -> 7.619137 | O5: =SUMIFS(Zepto_Data!$J$2:$J$3732,Zepto_Data!$A$2:$A$3732,ZP_Engine!$B$11,Zepto_Data!$L$2:$L$3732,ZP_Engine!$B$12,Zepto_Data!$K$2:$K$3732,ZP_Engine!$B$13,Zepto_Data!$M$2:$M$3732,ZP_Engine!$B$14) -> 2243080.6
B6: Value field (Y axis) | C6: Revenue (Rs)
B7: Aggregation | C7: Sum | F7: =IF('Zepto Dashboard'!$C$7="Count","Count of records",'Zepto Dashboard'!$C$7&" of "&'Zepto Dashboard'!$C$6)&" by "&'Zepto Dashboard'!$C$5 -> Sum of Revenue (Rs) by Category | O7: ="Split: "&IF('Zepto Dashboard'!$C$7="Count","Count of records",'Zepto Dashboard'!$C$7&" of "&'Zepto Dashboard'!$C$6)&" by "&'Zepto Dashboard'!$C$5&IF('Zepto Dashboard'!$C$8="None",""," and "&'Zepto Dashboard'!$C$8) -> Split: Sum of Revenue (Rs) by Category
B8: Split by (legend) | C8: None
B9: Sort | C9: Value: high to low
B10: Show top N | C10: 12
B11: FILTERS
B12: Category | C12: All
B13: Stock status | C13: All
B14: Weight category | C14: All
B15: Discount band | C15: All
B19: TOP-N BREAKDOWN (current selection)
B20: Item | C20: Value | D20: Share
B21: =IF(ZP_Engine!C45="","",ZP_Engine!C45) -> Cooking Essentials | C21: =IF(ZP_Engine!C45="","",ZP_Engine!D45) -> 337369 | D21: =IF(ZP_Engine!E45="","",ZP_Engine!E45) -> 0.15040431
B22: =IF(ZP_Engine!C46="","",ZP_Engine!C46) -> Munchies | C22: =IF(ZP_Engine!C46="","",ZP_Engine!D46) -> 337369 | D22: =IF(ZP_Engine!E46="","",ZP_Engine!E46) -> 0.15040431
B23: =IF(ZP_Engine!C47="","",ZP_Engine!C47) -> Paan Corner | C23: =IF(ZP_Engine!C47="","",ZP_Engine!D47) -> 270849 | D23: =IF(ZP_Engine!E47="","",ZP_Engine!E47) -> 0.12074867
B24: =IF(ZP_Engine!C48="","",ZP_Engine!C48) -> Personal Care | C24: =IF(ZP_Engine!C48="","",ZP_Engine!D48) -> 270849 | D24: =IF(ZP_Engine!E48="","",ZP_Engine!E48) -> 0.12074867
B25: =IF(ZP_Engine!C49="","",ZP_Engine!C49) -> Chocolates & Candies | C25: =IF(ZP_Engine!C49="","",ZP_Engine!D49) -> 224385 | D25: =IF(ZP_Engine!E49="","",ZP_Engine!E49) -> 0.1000343 | F25: ="Share of "&'Zepto Dashboard'!$C$6&" by "&'Zepto Dashboard'!$C$5&" (top N)" -> Share of Revenue (Rs) by Category (top N) | O25: ="SKUs: in stock vs out of stock (filters applied)" -> SKUs: in stock vs out of stock (filters applied)
B26: =IF(ZP_Engine!C50="","",ZP_Engine!C50) -> Ice Cream & Desserts | C26: =IF(ZP_Engine!C50="","",ZP_Engine!D50) -> 224385 | D26: =IF(ZP_Engine!E50="","",ZP_Engine!E50) -> 0.1000343
B27: =IF(ZP_Engine!C51="","",ZP_Engine!C51) -> Packaged Food | C27: =IF(ZP_Engine!C51="","",ZP_Engine!D51) -> 224385 | D27: =IF(ZP_Engine!E51="","",ZP_Engine!E51) -> 0.1000343
B28: =IF(ZP_Engine!C52="","",ZP_Engine!C52) -> Home & Cleaning | C28: =IF(ZP_Engine!C52="","",ZP_Engine!D52) -> 122661 | D28: =IF(ZP_Engine!E52="","",ZP_Engine!E52) -> 0.05468417
B29: =IF(ZP_Engine!C53="","",ZP_Engine!C53) -> Health & Hygiene | C29: =IF(ZP_Engine!C53="","",ZP_Engine!D53) -> 64180 | D29: =IF(ZP_Engine!E53="","",ZP_Engine!E53) -> 0.028612436
B30: =IF(ZP_Engine!C54="","",ZP_Engine!C54) -> Beverages | C30: =IF(ZP_Engine!C54="","",ZP_Engine!D54) -> 55051 | D30: =IF(ZP_Engine!E54="","",ZP_Engine!E54) -> 0.024542587
B31: =IF(ZP_Engine!C55="","",ZP_Engine!C55) -> Dairy, Bread & Batter | C31: =IF(ZP_Engine!C55="","",ZP_Engine!D55) -> 55051 | D31: =IF(ZP_Engine!E55="","",ZP_Engine!E55) -> 0.024542587
B32: =IF(ZP_Engine!C56="","",ZP_Engine!C56) -> Biscuits | C32: =IF(ZP_Engine!C56="","",ZP_Engine!D56) -> 25007.6 | D32: =IF(ZP_Engine!E56="","",ZP_Engine!E56) -> 0.011148775
B34: How to use
B35: 1. Change the yellow cells; charts, KPIs and the table recalculate.
B36: 2. "Group by" is the X axis; "Value field" + "Aggregation" is the Y axis.
B37: 3. "Split by" stacks the second chart by a second dimension.
B38: 4. Filters apply to every chart and KPI on this page.
B39: 5. Long lists (Country, City, Owner, Product) show the 20 most
B40: frequent items only. Dimensions with fewer items leave gaps.

Sheet ZP_Engine
A1: Calculation engine - do not edit. Drives the dashboard from the dropdown choices.
A2: dim # | B2: =MATCH('Zepto Dashboard'!$C$5,ZP_Lists!$A$2:$A$7,0) -> 1
A3: dim data col | B3: =INDEX(ZP_Lists!$B$2:$B$7,B2) -> 1
A4: measure # | B4: =MATCH('Zepto Dashboard'!$C$6,ZP_Lists!$D$2:$D$8,0) -> 1
A5: measure data col | B5: =INDEX(ZP_Lists!$E$2:$E$8,B4) -> 10
A6: aggregation | B6: ='Zepto Dashboard'!$C$7 -> Sum
A7: split # | B7: =IF('Zepto Dashboard'!$C$8="None",0,MATCH('Zepto Dashboard'!$C$8,ZP_Lists!$A$2:$A$7,0)) -> 0
A8: split data col | B8: =IF(B7=0,1,INDEX(ZP_Lists!$B$2:$B$7,B7)) -> 1
A9: top N | B9: ='Zepto Dashboard'!$C$10 -> 12
A10: sort | B10: ='Zepto Dashboard'!$C$9 -> Value: high to low
A11: crit: Category | B11: =IF('Zepto Dashboard'!$C$12="All","*",'Zepto Dashboard'!$C$12) -> *
A12: crit: Stock status | B12: =IF('Zepto Dashboard'!$C$13="All","*",'Zepto Dashboard'!$C$13) -> *
A13: crit: Weight category | B13: =IF('Zepto Dashboard'!$C$14="All","*",'Zepto Dashboard'!$C$14) -> *
A14: crit: Discount band | B14: =IF('Zepto Dashboard'!$C$15="All","*",'Zepto Dashboard'!$C$15) -> *
A18: split criteria | F18: =IF($B$7=0,"*",IF(INDEX(ZP_Lists!$L$2:$Q$21,1,$B$7)="","",INDEX(ZP_Lists!$L$2:$Q$21,1,$B$7))) -> * | G18: =IF($B$7=0,"",IF(INDEX(ZP_Lists!$L$2:$Q$21,2,$B$7)="","",INDEX(ZP_Lists!$L$2:$Q$21,2,$B$7))) | H18: =IF($B$7=0,"",IF(INDEX(ZP_Lists!$L$2:$Q$21,3,$B$7)="","",INDEX(ZP_Lists!$L$2:$Q$21,3,$B$7))) | I18: =IF($B$7=0,"",IF(INDEX(ZP_Lists!$L$2:$Q$21,4,$B$7)="","",INDEX(ZP_Lists!$L$2:$Q$21,4,$B$7))) | J18: =IF($B$7=0,"",IF(INDEX(ZP_Lists!$L$2:$Q$21,5,$B$7)="","",INDEX(ZP_Lists!$L$2:$Q$21,5,$B$7)))
A19: members -> | B19: member | C19: value | D19: rank | F19: =IF(F18="*","All",F18) -> All | G19: =IF(G18="*","All",G18) | H19: =IF(H18="*","All",H18) | I19: =IF(I18="*","All",I18) | J19: =IF(J18="*","All",J18)
A20: 1 | B20: =IF(INDEX(ZP_Lists!$L$2:$Q$21,A20,$B$2)="","",INDEX(ZP_Lists!$L$2:$Q$21,A20,$B$2)) -> Beverages | C20: =IF(B20="","",IF($B$6="Count",COUNTIFS(INDEX(ZPD,0,$B$3),B20,Zepto_Data!$A$2:$A$3732,$B$11,Zepto_Data!$L$2:$L$3732,$B$12,Zepto_Data!$K$2:$K$3732,$B$13,Zepto_Data!$M$2:$M$3732,$B$14),IF($B$6="Sum",SUMIFS(INDEX(ZPD,0,$B$5),INDEX(ZPD,0,$B$3),B20,Zepto_Data!$A$2:$A$3732,$B$11,Zepto_Data!$L$2:$L$3732,$B$12,Zepto_Data!$K$2:$K$3732,$B$13,Zepto_Data!$M$2:$M$3732,$B$14),IFERROR(SUMIFS(INDEX(ZPD,0,$B$5),INDEX(ZPD,0,$B$3),B20,Zepto_Data!$A$2:$A$3732,$B$11,Zepto_Data!$L$2:$L$3732,$B$12,Zepto_Data!$K$2:$K$3732,$B$13,Zepto_Data!$M$2:$M$3732,$B$14)/COUNTIFS(INDEX(ZPD,0,$B$3),B20,Zepto_Data!$A$2:$A$3732,$B$11,Zepto_Data!$L$2:$L$3732,$B$12,Zepto_Data!$K$2:$K$3732,$B$13,Zepto_Data!$M$2:$M$3732,$B$14),0)))) -> 55051 | D20: =IF(B20="","",IF($B$10="Natural order",A20,IF($B$10="Value: high to low",SUMPRODUCT(($B$20:$B$39<>"")*($C$20:$C$39>C20))+SUMPRODUCT(($B$20:B20<>"")*($C$20:C20=C20)),SUMPRODUCT(($B$20:$B$39<>"")*($C$20:$C$39<C20))+SUMPRODUCT(($B$20:B20<>"")*($C$20:C20=C20))))) -> 10 | F20: =IF(OR($B20="",F$18=""),"",IF($B$6="Count",COUNTIFS(INDEX(ZPD,0,$B$3),$B20,INDEX(ZPD,0,$B$8),F$18,Zepto_Data!$A$2:$A$3732,$B$11,Zepto_Data!$L$2:$L$3732,$B$12,Zepto_Data!$K$2:$K$3732,$B$13,Zepto_Data!$M$2:$M$3732,$B$14),IF($B$6="Sum",SUMIFS(INDEX(ZPD,0,$B$5),INDEX(ZPD,0,$B$3),$B20,INDEX(ZPD,0,$B$8),F$18,Zepto_Data!$A$2:$A$3732,$B$11,Zepto_Data!$L$2:$L$3732,$B$12,Zepto_Data!$K$2:$K$3732,$B$13,Zepto_Data!$M$2:$M$3732,$B$14),IFERROR(SUMIFS(INDEX(ZPD,0,$B$5),INDEX(ZPD,0,$B$3),$B20,INDEX(ZPD,0,$B$8),F$18,Zepto_Data!$A$2:$A$3732,$B$11,Zepto_Data!$L$2:$L$3732,$B$12,Zepto_Data!$K$2:$K$3732,$B$13,Zepto_Data!$M$2:$M$3732,$B$14)/COUNTIFS(INDEX(ZPD,0,$B$3),$B20,INDEX(ZPD,0,$B$8),F$18,Zepto_Data!$A$2:$A$3732,$B$11,Zepto_Data!$L$2:$L$3732,$B$12,Zepto_Data!$K$2:$K$3732,$B$13,Zepto_Data!$M$2:$M$3732,$B$14),0)))) -> 55051 | G20: =IF(OR($B20="",G$18=""),"",IF($B$6="Count",COUNTIFS(INDEX(ZPD,0,$B$3),$B20,INDEX(ZPD,0,$B$8),G$18,Zepto_Data!$A$2:$A$3732,$B$11,Zepto_Data!$L$2:$L$3732,$B$12,Zepto_Data!$K$2:$K$3732,$B$13,Zepto_Data!$M$2:$M$3732,$B$14),IF($B$6="Sum",SUMIFS(INDEX(ZPD,0,$B$5),INDEX(ZPD,0,$B$3),$B20,INDEX(ZPD,0,$B$8),G$18,Zepto_Data!$A$2:$A$3732,$B$11,Zepto_Data!$L$2:$L$3732,$B$12,Zepto_Data!$K$2:$K$3732,$B$13,Zepto_Data!$M$2:$M$3732,$B$14),IFERROR(SUMIFS(INDEX(ZPD,0,$B$5),INDEX(ZPD,0,$B$3),$B20,INDEX(ZPD,0,$B$8),G$18,Zepto_Data!$A$2:$A$3732,$B$11,Zepto_Data!$L$2:$L$3732,$B$12,Zepto_Data!$K$2:$K$3732,$B$13,Zepto_Data!$M$2:$M$3732,$B$14)/COUNTIFS(INDEX(ZPD,0,$B$3),$B20,INDEX(ZPD,0,$B$8),G$18,Zepto_Data!$A$2:$A$3732,$B$11,Zepto_Data!$L$2:$L$3732,$B$12,Zepto_Data!$K$2:$K$3732,$B$13,Zepto_Data!$M$2:$M$3732,$B$14),0)))) | H20: =IF(OR($B20="",H$18=""),"",IF($B$6="Count",COUNTIFS(INDEX(ZPD,0,$B$3),$B20,INDEX(ZPD,0,$B$8),H$18,Zepto_Data!$A$2:$A$3732,$B$11,Zepto_Data!$L$2:$L$3732,$B$12,Zepto_Data!$K$2:$K$3732,$B$13,Zepto_Data!$M$2:$M$3732,$B$14),IF($B$6="Sum",SUMIFS(INDEX(ZPD,0,$B$5),INDEX(ZPD,0,$B$3),$B20,INDEX(ZPD,0,$B$8),H$18,Zepto_Data!$A$2:$A$3732,$B$11,Zepto_Data!$L$2:$L$3732,$B$12,Zepto_Data!$K$2:$K$3732,$B$13,Zepto_Data!$M$2:$M$3732,$B$14),IFERROR(SUMIFS(INDEX(ZPD,0,$B$5),INDEX(ZPD,0,$B$3),$B20,INDEX(ZPD,0,$B$8),H$18,Zepto_Data!$A$2:$A$3732,$B$11,Zepto_Data!$L$2:$L$3732,$B$12,Zepto_Data!$K$2:$K$3732,$B$13,Zepto_Data!$M$2:$M$3732,$B$14)/COUNTIFS(INDEX(ZPD,0,$B$3),$B20,INDEX(ZPD,0,$B$8),H$18,Zepto_Data!$A$2:$A$3732,$B$11,Zepto_Data!$L$2:$L$3732,$B$12,Zepto_Data!$K$2:$K$3732,$B$13,Zepto_Data!$M$2:$M$3732,$B$14),0)))) | I20: =IF(OR($B20="",I$18=""),"",IF($B$6="Count",COUNTIFS(INDEX(ZPD,0,$B$3),$B20,INDEX(ZPD,0,$B$8),I$18,Zepto_Data!$A$2:$A$3732,$B$11,Zepto_Data!$L$2:$L$3732,$B$12,Zepto_Data!$K$2:$K$3732,$B$13,Zepto_Data!$M$2:$M$3732,$B$14),IF($B$6="Sum",SUMIFS(INDEX(ZPD,0,$B$5),INDEX(ZPD,0,$B$3),$B20,INDEX(ZPD,0,$B$8),I$18,Zepto_Data!$A$2:$A$3732,$B$11,Zepto_Data!$L$2:$L$3732,$B$12,Zepto_Data!$K$2:$K$3732,$B$13,Zepto_Data!$M$2:$M$3732,$B$14),IFERROR(SUMIFS(INDEX(ZPD,0,$B$5),INDEX(ZPD,0,$B$3),$B20,INDEX(ZPD,0,$B$8),I$18,Zepto_Data!$A$2:$A$3732,$B$11,Zepto_Data!$L$2:$L$3732,$B$12,Zepto_Data!$K$2:$K$3732,$B$13,Zepto_Data!$M$2:$M$3732,$B$14)/COUNTIFS(INDEX(ZPD,0,$B$3),$B20,INDEX(ZPD,0,$B$8),I$18,Zepto_Data!$A$2:$A$3732,$B$11,Zepto_Data!$L$2:$L$3732,$B$12,Zepto_Data!$K$2:$K$3732,$B$13,Zepto_Data!$M$2:$M$3732,$B$14),0)))) | J20: =IF(OR($B20="",J$18=""),"",IF($B$6="Count",COUNTIFS(INDEX(ZPD,0,$B$3),$B20,INDEX(ZPD,0,$B$8),J$18,Zepto_Data!$A$2:$A$3732,$B$11,Zepto_Data!$L$2:$L$3732,$B$12,Zepto_Data!$K$2:$K$3732,$B$13,Zepto_Data!$M$2:$M$3732,$B$14),IF($B$6="Sum",SUMIFS(INDEX(ZPD,0,$B$5),INDEX(ZPD,0,$B$3),$B20,INDEX(ZPD,0,$B$8),J$18,Zepto_Data!$A$2:$A$3732,$B$11,Zepto_Data!$L$2:$L$3732,$B$12,Zepto_Data!$K$2:$K$3732,$B$13,Zepto_Data!$M$2:$M$3732,$B$14),IFERROR(SUMIFS(INDEX(ZPD,0,$B$5),INDEX(ZPD,0,$B$3),$B20,INDEX(ZPD,0,$B$8),J$18,Zepto_Data!$A$2:$A$3732,$B$11,Zepto_Data!$L$2:$L$3732,$B$12,Zepto_Data!$K$2:$K$3732,$B$13,Zepto_Data!$M$2:$M$3732,$B$14)/COUNTIFS(INDEX(ZPD,0,$B$3),$B20,INDEX(ZPD,0,$B$8),J$18,Zepto_Data!$A$2:$A$3732,$B$11,Zepto_Data!$L$2:$L$3732,$B$12,Zepto_Data!$K$2:$K$3732,$B$13,Zepto_Data!$M$2:$M$3732,$B$14),0))))
A21: 2 | B21: =IF(INDEX(ZP_Lists!$L$2:$Q$21,A21,$B$2)="","",INDEX(ZP_Lists!$L$2:$Q$21,A21,$B$2)) -> Biscuits | C21: =IF(B21="","",IF($B$6="Count",COUNTIFS(INDEX(ZPD,0,$B$3),B21,Zepto_Data!$A$2:$A$3732,$B$11,Zepto_Data!$L$2:$L$3732,$B$12,Zepto_Data!$K$2:$K$3732,$B$13,Zepto_Data!$M$2:$M$3732,$B$14),IF($B$6="Sum",SUMIFS(INDEX(ZPD,0,$B$5),INDEX(ZPD,0,$B$3),B21,Zepto_Data!$A$2:$A$3732,$B$11,Zepto_Data!$L$2:$L$3732,$B$12,Zepto_Data!$K$2:$K$3732,$B$13,Zepto_Data!$M$2:$M$3732,$B$14),IFERROR(SUMIFS(INDEX(ZPD,0,$B$5),INDEX(ZPD,0,$B$3),B21,Zepto_Data!$A$2:$A$3732,$B$11,Zepto_Data!$L$2:$L$3732,$B$12,Zepto_Data!$K$2:$K$3732,$B$13,Zepto_Data!$M$2:$M$3732,$B$14)/COUNTIFS(INDEX(ZPD,0,$B$3),B21,Zepto_Data!$A$2:$A$3732,$B$11,Zepto_Data!$L$2:$L$3732,$B$12,Zepto_Data!$K$2:$K$3732,$B$13,Zepto_Data!$M$2:$M$3732,$B$14),0)))) -> 25007.6 | D21: =IF(B21="","",IF($B$10="Natural order",A21,IF($B$10="Value: high to low",SUMPRODUCT(($B$20:$B$39<>"")*($C$20:$C$39>C21))+SUMPRODUCT(($B$20:B21<>"")*($C$20:C21=C21)),SUMPRODUCT(($B$20:$B$39<>"")*($C$20:$C$39<C21))+SUMPRODUCT(($B$20:B21<>"")*($C$20:C21=C21))))) -> 12 | F21: =IF(OR($B21="",F$18=""),"",IF($B$6="Count",COUNTIFS(INDEX(ZPD,0,$B$3),$B21,INDEX(ZPD,0,$B$8),F$18,Zepto_Data!$A$2:$A$3732,$B$11,Zepto_Data!$L$2:$L$3732,$B$12,Zepto_Data!$K$2:$K$3732,$B$13,Zepto_Data!$M$2:$M$3732,$B$14),IF($B$6="Sum",SUMIFS(INDEX(ZPD,0,$B$5),INDEX(ZPD,0,$B$3),$B21,INDEX(ZPD,0,$B$8),F$18,Zepto_Data!$A$2:$A$3732,$B$11,Zepto_Data!$L$2:$L$3732,$B$12,Zepto_Data!$K$2:$K$3732,$B$13,Zepto_Data!$M$2:$M$3732,$B$14),IFERROR(SUMIFS(INDEX(ZPD,0,$B$5),INDEX(ZPD,0,$B$3),$B21,INDEX(ZPD,0,$B$8),F$18,Zepto_Data!$A$2:$A$3732,$B$11,Zepto_Data!$L$2:$L$3732,$B$12,Zepto_Data!$K$2:$K$3732,$B$13,Zepto_Data!$M$2:$M$3732,$B$14)/COUNTIFS(INDEX(ZPD,0,$B$3),$B21,INDEX(ZPD,0,$B$8),F$18,Zepto_Data!$A$2:$A$3732,$B$11,Zepto_Data!$L$2:$L$3732,$B$12,Zepto_Data!$K$2:$K$3732,$B$13,Zepto_Data!$M$2:$M$3732,$B$14),0)))) -> 25007.6 | G21: =IF(OR($B21="",G$18=""),"",IF($B$6="Count",COUNTIFS(INDEX(ZPD,0,$B$3),$B21,INDEX(ZPD,0,$B$8),G$18,Zepto_Data!$A$2:$A$3732,$B$11,Zepto_Data!$L$2:$L$3732,$B$12,Zepto_Data!$K$2:$K$3732,$B$13,Zepto_Data!$M$2:$M$3732,$B$14),IF($B$6="Sum",SUMIFS(INDEX(ZPD,0,$B$5),INDEX(ZPD,0,$B$3),$B21,INDEX(ZPD,0,$B$8),G$18,Zepto_Data!$A$2:$A$3732,$B$11,Zepto_Data!$L$2:$L$3732,$B$12,Zepto_Data!$K$2:$K$3732,$B$13,Zepto_Data!$M$2:$M$3732,$B$14),IFERROR(SUMIFS(INDEX(ZPD,0,$B$5),INDEX(ZPD,0,$B$3),$B21,INDEX(ZPD,0,$B$8),G$18,Zepto_Data!$A$2:$A$3732,$B$11,Zepto_Data!$L$2:$L$3732,$B$12,Zepto_Data!$K$2:$K$3732,$B$13,Zepto_Data!$M$2:$M$3732,$B$14)/COUNTIFS(INDEX(ZPD,0,$B$3),$B21,INDEX(ZPD,0,$B$8),G$18,Zepto_Data!$A$2:$A$3732,$B$11,Zepto_Data!$L$2:$L$3732,$B$12,Zepto_Data!$K$2:$K$3732,$B$13,Zepto_Data!$M$2:$M$3732,$B$14),0)))) | H21: =IF(OR($B21="",H$18=""),"",IF($B$6="Count",COUNTIFS(INDEX(ZPD,0,$B$3),$B21,INDEX(ZPD,0,$B$8),H$18,Zepto_Data!$A$2:$A$3732,$B$11,Zepto_Data!$L$2:$L$3732,$B$12,Zepto_Data!$K$2:$K$3732,$B$13,Zepto_Data!$M$2:$M$3732,$B$14),IF($B$6="Sum",SUMIFS(INDEX(ZPD,0,$B$5),INDEX(ZPD,0,$B$3),$B21,INDEX(ZPD,0,$B$8),H$18,Zepto_Data!$A$2:$A$3732,$B$11,Zepto_Data!$L$2:$L$3732,$B$12,Zepto_Data!$K$2:$K$3732,$B$13,Zepto_Data!$M$2:$M$3732,$B$14),IFERROR(SUMIFS(INDEX(ZPD,0,$B$5),INDEX(ZPD,0,$B$3),$B21,INDEX(ZPD,0,$B$8),H$18,Zepto_Data!$A$2:$A$3732,$B$11,Zepto_Data!$L$2:$L$3732,$B$12,Zepto_Data!$K$2:$K$3732,$B$13,Zepto_Data!$M$2:$M$3732,$B$14)/COUNTIFS(INDEX(ZPD,0,$B$3),$B21,INDEX(ZPD,0,$B$8),H$18,Zepto_Data!$A$2:$A$3732,$B$11,Zepto_Data!$L$2:$L$3732,$B$12,Zepto_Data!$K$2:$K$3732,$B$13,Zepto_Data!$M$2:$M$3732,$B$14),0)))) | I21: =IF(OR($B21="",I$18=""),"",IF($B$6="Count",COUNTIFS(INDEX(ZPD,0,$B$3),$B21,INDEX(ZPD,0,$B$8),I$18,Zepto_Data!$A$2:$A$3732,$B$11,Zepto_Data!$L$2:$L$3732,$B$12,Zepto_Data!$K$2:$K$3732,$B$13,Zepto_Data!$M$2:$M$3732,$B$14),IF($B$6="Sum",SUMIFS(INDEX(ZPD,0,$B$5),INDEX(ZPD,0,$B$3),$B21,INDEX(ZPD,0,$B$8),I$18,Zepto_Data!$A$2:$A$3732,$B$11,Zepto_Data!$L$2:$L$3732,$B$12,Zepto_Data!$K$2:$K$3732,$B$13,Zepto_Data!$M$2:$M$3732,$B$14),IFERROR(SUMIFS(INDEX(ZPD,0,$B$5),INDEX(ZPD,0,$B$3),$B21,INDEX(ZPD,0,$B$8),I$18,Zepto_Data!$A$2:$A$3732,$B$11,Zepto_Data!$L$2:$L$3732,$B$12,Zepto_Data!$K$2:$K$3732,$B$13,Zepto_Data!$M$2:$M$3732,$B$14)/COUNTIFS(INDEX(ZPD,0,$B$3),$B21,INDEX(ZPD,0,$B$8),I$18,Zepto_Data!$A$2:$A$3732,$B$11,Zepto_Data!$L$2:$L$3732,$B$12,Zepto_Data!$K$2:$K$3732,$B$13,Zepto_Data!$M$2:$M$3732,$B$14),0)))) | J21: =IF(OR($B21="",J$18=""),"",IF($B$6="Count",COUNTIFS(INDEX(ZPD,0,$B$3),$B21,INDEX(ZPD,0,$B$8),J$18,Zepto_Data!$A$2:$A$3732,$B$11,Zepto_Data!$L$2:$L$3732,$B$12,Zepto_Data!$K$2:$K$3732,$B$13,Zepto_Data!$M$2:$M$3732,$B$14),IF($B$6="Sum",SUMIFS(INDEX(ZPD,0,$B$5),INDEX(ZPD,0,$B$3),$B21,INDEX(ZPD,0,$B$8),J$18,Zepto_Data!$A$2:$A$3732,$B$11,Zepto_Data!$L$2:$L$3732,$B$12,Zepto_Data!$K$2:$K$3732,$B$13,Zepto_Data!$M$2:$M$3732,$B$14),IFERROR(SUMIFS(INDEX(ZPD,0,$B$5),INDEX(ZPD,0,$B$3),$B21,INDEX(ZPD,0,$B$8),J$18,Zepto_Data!$A$2:$A$3732,$B$11,Zepto_Data!$L$2:$L$3732,$B$12,Zepto_Data!$K$2:$K$3732,$B$13,Zepto_Data!$M$2:$M$3732,$B$14)/COUNTIFS(INDEX(ZPD,0,$B$3),$B21,INDEX(ZPD,0,$B$8),J$18,Zepto_Data!$A$2:$A$3732,$B$11,Zepto_Data!$L$2:$L$3732,$B$12,Zepto_Data!$K$2:$K$3732,$B$13,Zepto_Data!$M$2:$M$3732,$B$14),0))))
A22: 3 | B22: =IF(INDEX(ZP_Lists!$L$2:$Q$21,A22,$B$2)="","",INDEX(ZP_Lists!$L$2:$Q$21,A22,$B$2)) -> Chocolates & Candies | C22: =IF(B22="","",IF($B$6="Count",COUNTIFS(INDEX(ZPD,0,$B$3),B22,Zepto_Data!$A$2:$A$3732,$B$11,Zepto_Data!$L$2:$L$3732,$B$12,Zepto_Data!$K$2:$K$3732,$B$13,Zepto_Data!$M$2:$M$3732,$B$14),IF($B$6="Sum",SUMIFS(INDEX(ZPD,0,$B$5),INDEX(ZPD,0,$B$3),B22,Zepto_Data!$A$2:$A$3732,$B$11,Zepto_Data!$L$2:$L$3732,$B$12,Zepto_Data!$K$2:$K$3732,$B$13,Zepto_Data!$M$2:$M$3732,$B$14),IFERROR(SUMIFS(INDEX(ZPD,0,$B$5),INDEX(ZPD,0,$B$3),B22,Zepto_Data!$A$2:$A$3732,$B$11,Zepto_Data!$L$2:$L$3732,$B$12,Zepto_Data!$K$2:$K$3732,$B$13,Zepto_Data!$M$2:$M$3732,$B$14)/COUNTIFS(INDEX(ZPD,0,$B$3),B22,Zepto_Data!$A$2:$A$3732,$B$11,Zepto_Data!$L$2:$L$3732,$B$12,Zepto_Data!$K$2:$K$3732,$B$13,Zepto_Data!$M$2:$M$3732,$B$14),0)))) -> 224385 | D22: =IF(B22="","",IF($B$10="Natural order",A22,IF($B$10="Value: high to low",SUMPRODUCT(($B$20:$B$39<>"")*($C$20:$C$39>C22))+SUMPRODUCT(($B$20:B22<>"")*($C$20:C22=C22)),SUMPRODUCT(($B$20:$B$39<>"")*($C$20:$C$39<C22))+SUMPRODUCT(($B$20:B22<>"")*($C$20:C22=C22))))) -> 5 | F22: =IF(OR($B22="",F$18=""),"",IF($B$6="Count",COUNTIFS(INDEX(ZPD,0,$B$3),$B22,INDEX(ZPD,0,$B$8),F$18,Zepto_Data!$A$2:$A$3732,$B$11,Zepto_Data!$L$2:$L$3732,$B$12,Zepto_Data!$K$2:$K$3732,$B$13,Zepto_Data!$M$2:$M$3732,$B$14),IF($B$6="Sum",SUMIFS(INDEX(ZPD,0,$B$5),INDEX(ZPD,0,$B$3),$B22,INDEX(ZPD,0,$B$8),F$18,Zepto_Data!$A$2:$A$3732,$B$11,Zepto_Data!$L$2:$L$3732,$B$12,Zepto_Data!$K$2:$K$3732,$B$13,Zepto_Data!$M$2:$M$3732,$B$14),IFERROR(SUMIFS(INDEX(ZPD,0,$B$5),INDEX(ZPD,0,$B$3),$B22,INDEX(ZPD,0,$B$8),F$18,Zepto_Data!$A$2:$A$3732,$B$11,Zepto_Data!$L$2:$L$3732,$B$12,Zepto_Data!$K$2:$K$3732,$B$13,Zepto_Data!$M$2:$M$3732,$B$14)/COUNTIFS(INDEX(ZPD,0,$B$3),$B22,INDEX(ZPD,0,$B$8),F$18,Zepto_Data!$A$2:$A$3732,$B$11,Zepto_Data!$L$2:$L$3732,$B$12,Zepto_Data!$K$2:$K$3732,$B$13,Zepto_Data!$M$2:$M$3732,$B$14),0)))) -> 224385 | G22: =IF(OR($B22="",G$18=""),"",IF($B$6="Count",COUNTIFS(INDEX(ZPD,0,$B$3),$B22,INDEX(ZPD,0,$B$8),G$18,Zepto_Data!$A$2:$A$3732,$B$11,Zepto_Data!$L$2:$L$3732,$B$12,Zepto_Data!$K$2:$K$3732,$B$13,Zepto_Data!$M$2:$M$3732,$B$14),IF($B$6="Sum",SUMIFS(INDEX(ZPD,0,$B$5),INDEX(ZPD,0,$B$3),$B22,INDEX(ZPD,0,$B$8),G$18,Zepto_Data!$A$2:$A$3732,$B$11,Zepto_Data!$L$2:$L$3732,$B$12,Zepto_Data!$K$2:$K$3732,$B$13,Zepto_Data!$M$2:$M$3732,$B$14),IFERROR(SUMIFS(INDEX(ZPD,0,$B$5),INDEX(ZPD,0,$B$3),$B22,INDEX(ZPD,0,$B$8),G$18,Zepto_Data!$A$2:$A$3732,$B$11,Zepto_Data!$L$2:$L$3732,$B$12,Zepto_Data!$K$2:$K$3732,$B$13,Zepto_Data!$M$2:$M$3732,$B$14)/COUNTIFS(INDEX(ZPD,0,$B$3),$B22,INDEX(ZPD,0,$B$8),G$18,Zepto_Data!$A$2:$A$3732,$B$11,Zepto_Data!$L$2:$L$3732,$B$12,Zepto_Data!$K$2:$K$3732,$B$13,Zepto_Data!$M$2:$M$3732,$B$14),0)))) | H22: =IF(OR($B22="",H$18=""),"",IF($B$6="Count",COUNTIFS(INDEX(ZPD,0,$B$3),$B22,INDEX(ZPD,0,$B$8),H$18,Zepto_Data!$A$2:$A$3732,$B$11,Zepto_Data!$L$2:$L$3732,$B$12,Zepto_Data!$K$2:$K$3732,$B$13,Zepto_Data!$M$2:$M$3732,$B$14),IF($B$6="Sum",SUMIFS(INDEX(ZPD,0,$B$5),INDEX(ZPD,0,$B$3),$B22,INDEX(ZPD,0,$B$8),H$18,Zepto_Data!$A$2:$A$3732,$B$11,Zepto_Data!$L$2:$L$3732,$B$12,Zepto_Data!$K$2:$K$3732,$B$13,Zepto_Data!$M$2:$M$3732,$B$14),IFERROR(SUMIFS(INDEX(ZPD,0,$B$5),INDEX(ZPD,0,$B$3),$B22,INDEX(ZPD,0,$B$8),H$18,Zepto_Data!$A$2:$A$3732,$B$11,Zepto_Data!$L$2:$L$3732,$B$12,Zepto_Data!$K$2:$K$3732,$B$13,Zepto_Data!$M$2:$M$3732,$B$14)/COUNTIFS(INDEX(ZPD,0,$B$3),$B22,INDEX(ZPD,0,$B$8),H$18,Zepto_Data!$A$2:$A$3732,$B$11,Zepto_Data!$L$2:$L$3732,$B$12,Zepto_Data!$K$2:$K$3732,$B$13,Zepto_Data!$M$2:$M$3732,$B$14),0)))) | I22: =IF(OR($B22="",I$18=""),"",IF($B$6="Count",COUNTIFS(INDEX(ZPD,0,$B$3),$B22,INDEX(ZPD,0,$B$8),I$18,Zepto_Data!$A$2:$A$3732,$B$11,Zepto_Data!$L$2:$L$3732,$B$12,Zepto_Data!$K$2:$K$3732,$B$13,Zepto_Data!$M$2:$M$3732,$B$14),IF($B$6="Sum",SUMIFS(INDEX(ZPD,0,$B$5),INDEX(ZPD,0,$B$3),$B22,INDEX(ZPD,0,$B$8),I$18,Zepto_Data!$A$2:$A$3732,$B$11,Zepto_Data!$L$2:$L$3732,$B$12,Zepto_Data!$K$2:$K$3732,$B$13,Zepto_Data!$M$2:$M$3732,$B$14),IFERROR(SUMIFS(INDEX(ZPD,0,$B$5),INDEX(ZPD,0,$B$3),$B22,INDEX(ZPD,0,$B$8),I$18,Zepto_Data!$A$2:$A$3732,$B$11,Zepto_Data!$L$2:$L$3732,$B$12,Zepto_Data!$K$2:$K$3732,$B$13,Zepto_Data!$M$2:$M$3732,$B$14)/COUNTIFS(INDEX(ZPD,0,$B$3),$B22,INDEX(ZPD,0,$B$8),I$18,Zepto_Data!$A$2:$A$3732,$B$11,Zepto_Data!$L$2:$L$3732,$B$12,Zepto_Data!$K$2:$K$3732,$B$13,Zepto_Data!$M$2:$M$3732,$B$14),0)))) | J22: =IF(OR($B22="",J$18=""),"",IF($B$6="Count",COUNTIFS(INDEX(ZPD,0,$B$3),$B22,INDEX(ZPD,0,$B$8),J$18,Zepto_Data!$A$2:$A$3732,$B$11,Zepto_Data!$L$2:$L$3732,$B$12,Zepto_Data!$K$2:$K$3732,$B$13,Zepto_Data!$M$2:$M$3732,$B$14),IF($B$6="Sum",SUMIFS(INDEX(ZPD,0,$B$5),INDEX(ZPD,0,$B$3),$B22,INDEX(ZPD,0,$B$8),J$18,Zepto_Data!$A$2:$A$3732,$B$11,Zepto_Data!$L$2:$L$3732,$B$12,Zepto_Data!$K$2:$K$3732,$B$13,Zepto_Data!$M$2:$M$3732,$B$14),IFERROR(SUMIFS(INDEX(ZPD,0,$B$5),INDEX(ZPD,0,$B$3),$B22,INDEX(ZPD,0,$B$8),J$18,Zepto_Data!$A$2:$A$3732,$B$11,Zepto_Data!$L$2:$L$3732,$B$12,Zepto_Data!$K$2:$K$3732,$B$13,Zepto_Data!$M$2:$M$3732,$B$14)/COUNTIFS(INDEX(ZPD,0,$B$3),$B22,INDEX(ZPD,0,$B$8),J$18,Zepto_Data!$A$2:$A$3732,$B$11,Zepto_Data!$L$2:$L$3732,$B$12,Zepto_Data!$K$2:$K$3732,$B$13,Zepto_Data!$M$2:$M$3732,$B$14),0))))
A23: 4 | B23: =IF(INDEX(ZP_Lists!$L$2:$Q$21,A23,$B$2)="","",INDEX(ZP_Lists!$L$2:$Q$21,A23,$B$2)) -> Cooking Essentials | C23: =IF(B23="","",IF($B$6="Count",COUNTIFS(INDEX(ZPD,0,$B$3),B23,Zepto_Data!$A$2:$A$3732,$B$11,Zepto_Data!$L$2:$L$3732,$B$12,Zepto_Data!$K$2:$K$3732,$B$13,Zepto_Data!$M$2:$M$3732,$B$14),IF($B$6="Sum",SUMIFS(INDEX(ZPD,0,$B$5),INDEX(ZPD,0,$B$3),B23,Zepto_Data!$A$2:$A$3732,$B$11,Zepto_Data!$L$2:$L$3732,$B$12,Zepto_Data!$K$2:$K$3732,$B$13,Zepto_Data!$M$2:$M$3732,$B$14),IFERROR(SUMIFS(INDEX(ZPD,0,$B$5),INDEX(ZPD,0,$B$3),B23,Zepto_Data!$A$2:$A$3732,$B$11,Zepto_Data!$L$2:$L$3732,$B$12,Zepto_Data!$K$2:$K$3732,$B$13,Zepto_Data!$M$2:$M$3732,$B$14)/COUNTIFS(INDEX(ZPD,0,$B$3),B23,Zepto_Data!$A$2:$A$3732,$B$11,Zepto_Data!$L$2:$L$3732,$B$12,Zepto_Data!$K$2:$K$3732,$B$13,Zepto_Data!$M$2:$M$3732,$B$14),0)))) -> 337369 | D23: =IF(B23="","",IF($B$10="Natural order",A23,IF($B$10="Value: high to low",SUMPRODUCT(($B$20:$B$39<>"")*($C$20:$C$39>C23))+SUMPRODUCT(($B$20:B23<>"")*($C$20:C23=C23)),SUMPRODUCT(($B$20:$B$39<>"")*($C$20:$C$39<C23))+SUMPRODUCT(($B$20:B23<>"")*($C$20:C23=C23))))) -> 1 | F23: =IF(OR($B23="",F$18=""),"",IF($B$6="Count",COUNTIFS(INDEX(ZPD,0,$B$3),$B23,INDEX(ZPD,0,$B$8),F$18,Zepto_Data!$A$2:$A$3732,$B$11,Zepto_Data!$L$2:$L$3732,$B$12,Zepto_Data!$K$2:$K$3732,$B$13,Zepto_Data!$M$2:$M$3732,$B$14),IF($B$6="Sum",SUMIFS(INDEX(ZPD,0,$B$5),INDEX(ZPD,0,$B$3),$B23,INDEX(ZPD,0,$B$8),F$18,Zepto_Data!$A$2:$A$3732,$B$11,Zepto_Data!$L$2:$L$3732,$B$12,Zepto_Data!$K$2:$K$3732,$B$13,Zepto_Data!$M$2:$M$3732,$B$14),IFERROR(SUMIFS(INDEX(ZPD,0,$B$5),INDEX(ZPD,0,$B$3),$B23,INDEX(ZPD,0,$B$8),F$18,Zepto_Data!$A$2:$A$3732,$B$11,Zepto_Data!$L$2:$L$3732,$B$12,Zepto_Data!$K$2:$K$3732,$B$13,Zepto_Data!$M$2:$M$3732,$B$14)/COUNTIFS(INDEX(ZPD,0,$B$3),$B23,INDEX(ZPD,0,$B$8),F$18,Zepto_Data!$A$2:$A$3732,$B$11,Zepto_Data!$L$2:$L$3732,$B$12,Zepto_Data!$K$2:$K$3732,$B$13,Zepto_Data!$M$2:$M$3732,$B$14),0)))) -> 337369 | G23: =IF(OR($B23="",G$18=""),"",IF($B$6="Count",COUNTIFS(INDEX(ZPD,0,$B$3),$B23,INDEX(ZPD,0,$B$8),G$18,Zepto_Data!$A$2:$A$3732,$B$11,Zepto_Data!$L$2:$L$3732,$B$12,Zepto_Data!$K$2:$K$3732,$B$13,Zepto_Data!$M$2:$M$3732,$B$14),IF($B$6="Sum",SUMIFS(INDEX(ZPD,0,$B$5),INDEX(ZPD,0,$B$3),$B23,INDEX(ZPD,0,$B$8),G$18,Zepto_Data!$A$2:$A$3732,$B$11,Zepto_Data!$L$2:$L$3732,$B$12,Zepto_Data!$K$2:$K$3732,$B$13,Zepto_Data!$M$2:$M$3732,$B$14),IFERROR(SUMIFS(INDEX(ZPD,0,$B$5),INDEX(ZPD,0,$B$3),$B23,INDEX(ZPD,0,$B$8),G$18,Zepto_Data!$A$2:$A$3732,$B$11,Zepto_Data!$L$2:$L$3732,$B$12,Zepto_Data!$K$2:$K$3732,$B$13,Zepto_Data!$M$2:$M$3732,$B$14)/COUNTIFS(INDEX(ZPD,0,$B$3),$B23,INDEX(ZPD,0,$B$8),G$18,Zepto_Data!$A$2:$A$3732,$B$11,Zepto_Data!$L$2:$L$3732,$B$12,Zepto_Data!$K$2:$K$3732,$B$13,Zepto_Data!$M$2:$M$3732,$B$14),0)))) | H23: =IF(OR($B23="",H$18=""),"",IF($B$6="Count",COUNTIFS(INDEX(ZPD,0,$B$3),$B23,INDEX(ZPD,0,$B$8),H$18,Zepto_Data!$A$2:$A$3732,$B$11,Zepto_Data!$L$2:$L$3732,$B$12,Zepto_Data!$K$2:$K$3732,$B$13,Zepto_Data!$M$2:$M$3732,$B$14),IF($B$6="Sum",SUMIFS(INDEX(ZPD,0,$B$5),INDEX(ZPD,0,$B$3),$B23,INDEX(ZPD,0,$B$8),H$18,Zepto_Data!$A$2:$A$3732,$B$11,Zepto_Data!$L$2:$L$3732,$B$12,Zepto_Data!$K$2:$K$3732,$B$13,Zepto_Data!$M$2:$M$3732,$B$14),IFERROR(SUMIFS(INDEX(ZPD,0,$B$5),INDEX(ZPD,0,$B$3),$B23,INDEX(ZPD,0,$B$8),H$18,Zepto_Data!$A$2:$A$3732,$B$11,Zepto_Data!$L$2:$L$3732,$B$12,Zepto_Data!$K$2:$K$3732,$B$13,Zepto_Data!$M$2:$M$3732,$B$14)/COUNTIFS(INDEX(ZPD,0,$B$3),$B23,INDEX(ZPD,0,$B$8),H$18,Zepto_Data!$A$2:$A$3732,$B$11,Zepto_Data!$L$2:$L$3732,$B$12,Zepto_Data!$K$2:$K$3732,$B$13,Zepto_Data!$M$2:$M$3732,$B$14),0)))) | I23: =IF(OR($B23="",I$18=""),"",IF($B$6="Count",COUNTIFS(INDEX(ZPD,0,$B$3),$B23,INDEX(ZPD,0,$B$8),I$18,Zepto_Data!$A$2:$A$3732,$B$11,Zepto_Data!$L$2:$L$3732,$B$12,Zepto_Data!$K$2:$K$3732,$B$13,Zepto_Data!$M$2:$M$3732,$B$14),IF($B$6="Sum",SUMIFS(INDEX(ZPD,0,$B$5),INDEX(ZPD,0,$B$3),$B23,INDEX(ZPD,0,$B$8),I$18,Zepto_Data!$A$2:$A$3732,$B$11,Zepto_Data!$L$2:$L$3732,$B$12,Zepto_Data!$K$2:$K$3732,$B$13,Zepto_Data!$M$2:$M$3732,$B$14),IFERROR(SUMIFS(INDEX(ZPD,0,$B$5),INDEX(ZPD,0,$B$3),$B23,INDEX(ZPD,0,$B$8),I$18,Zepto_Data!$A$2:$A$3732,$B$11,Zepto_Data!$L$2:$L$3732,$B$12,Zepto_Data!$K$2:$K$3732,$B$13,Zepto_Data!$M$2:$M$3732,$B$14)/COUNTIFS(INDEX(ZPD,0,$B$3),$B23,INDEX(ZPD,0,$B$8),I$18,Zepto_Data!$A$2:$A$3732,$B$11,Zepto_Data!$L$2:$L$3732,$B$12,Zepto_Data!$K$2:$K$3732,$B$13,Zepto_Data!$M$2:$M$3732,$B$14),0)))) | J23: =IF(OR($B23="",J$18=""),"",IF($B$6="Count",COUNTIFS(INDEX(ZPD,0,$B$3),$B23,INDEX(ZPD,0,$B$8),J$18,Zepto_Data!$A$2:$A$3732,$B$11,Zepto_Data!$L$2:$L$3732,$B$12,Zepto_Data!$K$2:$K$3732,$B$13,Zepto_Data!$M$2:$M$3732,$B$14),IF($B$6="Sum",SUMIFS(INDEX(ZPD,0,$B$5),INDEX(ZPD,0,$B$3),$B23,INDEX(ZPD,0,$B$8),J$18,Zepto_Data!$A$2:$A$3732,$B$11,Zepto_Data!$L$2:$L$3732,$B$12,Zepto_Data!$K$2:$K$3732,$B$13,Zepto_Data!$M$2:$M$3732,$B$14),IFERROR(SUMIFS(INDEX(ZPD,0,$B$5),INDEX(ZPD,0,$B$3),$B23,INDEX(ZPD,0,$B$8),J$18,Zepto_Data!$A$2:$A$3732,$B$11,Zepto_Data!$L$2:$L$3732,$B$12,Zepto_Data!$K$2:$K$3732,$B$13,Zepto_Data!$M$2:$M$3732,$B$14)/COUNTIFS(INDEX(ZPD,0,$B$3),$B23,INDEX(ZPD,0,$B$8),J$18,Zepto_Data!$A$2:$A$3732,$B$11,Zepto_Data!$L$2:$L$3732,$B$12,Zepto_Data!$K$2:$K$3732,$B$13,Zepto_Data!$M$2:$M$3732,$B$14),0))))
A24: 5 | B24: =IF(INDEX(ZP_Lists!$L$2:$Q$21,A24,$B$2)="","",INDEX(ZP_Lists!$L$2:$Q$21,A24,$B$2)) -> Dairy, Bread & Batter | C24: =IF(B24="","",IF($B$6="Count",COUNTIFS(INDEX(ZPD,0,$B$3),B24,Zepto_Data!$A$2:$A$3732,$B$11,Zepto_Data!$L$2:$L$3732,$B$12,Zepto_Data!$K$2:$K$3732,$B$13,Zepto_Data!$M$2:$M$3732,$B$14),IF($B$6="Sum",SUMIFS(INDEX(ZPD,0,$B$5),INDEX(ZPD,0,$B$3),B24,Zepto_Data!$A$2:$A$3732,$B$11,Zepto_Data!$L$2:$L$3732,$B$12,Zepto_Data!$K$2:$K$3732,$B$13,Zepto_Data!$M$2:$M$3732,$B$14),IFERROR(SUMIFS(INDEX(ZPD,0,$B$5),INDEX(ZPD,0,$B$3),B24,Zepto_Data!$A$2:$A$3732,$B$11,Zepto_Data!$L$2:$L$3732,$B$12,Zepto_Data!$K$2:$K$3732,$B$13,Zepto_Data!$M$2:$M$3732,$B$14)/COUNTIFS(INDEX(ZPD,0,$B$3),B24,Zepto_Data!$A$2:$A$3732,$B$11,Zepto_Data!$L$2:$L$3732,$B$12,Zepto_Data!$K$2:$K$3732,$B$13,Zepto_Data!$M$2:$M$3732,$B$14),0)))) -> 55051 | D24: =IF(B24="","",IF($B$10="Natural order",A24,IF($B$10="Value: high to low",SUMPRODUCT(($B$20:$B$39<>"")*($C$20:$C$39>C24))+SUMPRODUCT(($B$20:B24<>"")*($C$20:C24=C24)),SUMPRODUCT(($B$20:$B$39<>"")*($C$20:$C$39<C24))+SUMPRODUCT(($B$20:B24<>"")*($C$20:C24=C24))))) -> 11 | F24: =IF(OR($B24="",F$18=""),"",IF($B$6="Count",COUNTIFS(INDEX(ZPD,0,$B$3),$B24,INDEX(ZPD,0,$B$8),F$18,Zepto_Data!$A$2:$A$3732,$B$11,Zepto_Data!$L$2:$L$3732,$B$12,Zepto_Data!$K$2:$K$3732,$B$13,Zepto_Data!$M$2:$M$3732,$B$14),IF($B$6="Sum",SUMIFS(INDEX(ZPD,0,$B$5),INDEX(ZPD,0,$B$3),$B24,INDEX(ZPD,0,$B$8),F$18,Zepto_Data!$A$2:$A$3732,$B$11,Zepto_Data!$L$2:$L$3732,$B$12,Zepto_Data!$K$2:$K$3732,$B$13,Zepto_Data!$M$2:$M$3732,$B$14),IFERROR(SUMIFS(INDEX(ZPD,0,$B$5),INDEX(ZPD,0,$B$3),$B24,INDEX(ZPD,0,$B$8),F$18,Zepto_Data!$A$2:$A$3732,$B$11,Zepto_Data!$L$2:$L$3732,$B$12,Zepto_Data!$K$2:$K$3732,$B$13,Zepto_Data!$M$2:$M$3732,$B$14)/COUNTIFS(INDEX(ZPD,0,$B$3),$B24,INDEX(ZPD,0,$B$8),F$18,Zepto_Data!$A$2:$A$3732,$B$11,Zepto_Data!$L$2:$L$3732,$B$12,Zepto_Data!$K$2:$K$3732,$B$13,Zepto_Data!$M$2:$M$3732,$B$14),0)))) -> 55051 | G24: =IF(OR($B24="",G$18=""),"",IF($B$6="Count",COUNTIFS(INDEX(ZPD,0,$B$3),$B24,INDEX(ZPD,0,$B$8),G$18,Zepto_Data!$A$2:$A$3732,$B$11,Zepto_Data!$L$2:$L$3732,$B$12,Zepto_Data!$K$2:$K$3732,$B$13,Zepto_Data!$M$2:$M$3732,$B$14),IF($B$6="Sum",SUMIFS(INDEX(ZPD,0,$B$5),INDEX(ZPD,0,$B$3),$B24,INDEX(ZPD,0,$B$8),G$18,Zepto_Data!$A$2:$A$3732,$B$11,Zepto_Data!$L$2:$L$3732,$B$12,Zepto_Data!$K$2:$K$3732,$B$13,Zepto_Data!$M$2:$M$3732,$B$14),IFERROR(SUMIFS(INDEX(ZPD,0,$B$5),INDEX(ZPD,0,$B$3),$B24,INDEX(ZPD,0,$B$8),G$18,Zepto_Data!$A$2:$A$3732,$B$11,Zepto_Data!$L$2:$L$3732,$B$12,Zepto_Data!$K$2:$K$3732,$B$13,Zepto_Data!$M$2:$M$3732,$B$14)/COUNTIFS(INDEX(ZPD,0,$B$3),$B24,INDEX(ZPD,0,$B$8),G$18,Zepto_Data!$A$2:$A$3732,$B$11,Zepto_Data!$L$2:$L$3732,$B$12,Zepto_Data!$K$2:$K$3732,$B$13,Zepto_Data!$M$2:$M$3732,$B$14),0)))) | H24: =IF(OR($B24="",H$18=""),"",IF($B$6="Count",COUNTIFS(INDEX(ZPD,0,$B$3),$B24,INDEX(ZPD,0,$B$8),H$18,Zepto_Data!$A$2:$A$3732,$B$11,Zepto_Data!$L$2:$L$3732,$B$12,Zepto_Data!$K$2:$K$3732,$B$13,Zepto_Data!$M$2:$M$3732,$B$14),IF($B$6="Sum",SUMIFS(INDEX(ZPD,0,$B$5),INDEX(ZPD,0,$B$3),$B24,INDEX(ZPD,0,$B$8),H$18,Zepto_Data!$A$2:$A$3732,$B$11,Zepto_Data!$L$2:$L$3732,$B$12,Zepto_Data!$K$2:$K$3732,$B$13,Zepto_Data!$M$2:$M$3732,$B$14),IFERROR(SUMIFS(INDEX(ZPD,0,$B$5),INDEX(ZPD,0,$B$3),$B24,INDEX(ZPD,0,$B$8),H$18,Zepto_Data!$A$2:$A$3732,$B$11,Zepto_Data!$L$2:$L$3732,$B$12,Zepto_Data!$K$2:$K$3732,$B$13,Zepto_Data!$M$2:$M$3732,$B$14)/COUNTIFS(INDEX(ZPD,0,$B$3),$B24,INDEX(ZPD,0,$B$8),H$18,Zepto_Data!$A$2:$A$3732,$B$11,Zepto_Data!$L$2:$L$3732,$B$12,Zepto_Data!$K$2:$K$3732,$B$13,Zepto_Data!$M$2:$M$3732,$B$14),0)))) | I24: =IF(OR($B24="",I$18=""),"",IF($B$6="Count",COUNTIFS(INDEX(ZPD,0,$B$3),$B24,INDEX(ZPD,0,$B$8),I$18,Zepto_Data!$A$2:$A$3732,$B$11,Zepto_Data!$L$2:$L$3732,$B$12,Zepto_Data!$K$2:$K$3732,$B$13,Zepto_Data!$M$2:$M$3732,$B$14),IF($B$6="Sum",SUMIFS(INDEX(ZPD,0,$B$5),INDEX(ZPD,0,$B$3),$B24,INDEX(ZPD,0,$B$8),I$18,Zepto_Data!$A$2:$A$3732,$B$11,Zepto_Data!$L$2:$L$3732,$B$12,Zepto_Data!$K$2:$K$3732,$B$13,Zepto_Data!$M$2:$M$3732,$B$14),IFERROR(SUMIFS(INDEX(ZPD,0,$B$5),INDEX(ZPD,0,$B$3),$B24,INDEX(ZPD,0,$B$8),I$18,Zepto_Data!$A$2:$A$3732,$B$11,Zepto_Data!$L$2:$L$3732,$B$12,Zepto_Data!$K$2:$K$3732,$B$13,Zepto_Data!$M$2:$M$3732,$B$14)/COUNTIFS(INDEX(ZPD,0,$B$3),$B24,INDEX(ZPD,0,$B$8),I$18,Zepto_Data!$A$2:$A$3732,$B$11,Zepto_Data!$L$2:$L$3732,$B$12,Zepto_Data!$K$2:$K$3732,$B$13,Zepto_Data!$M$2:$M$3732,$B$14),0)))) | J24: =IF(OR($B24="",J$18=""),"",IF($B$6="Count",COUNTIFS(INDEX(ZPD,0,$B$3),$B24,INDEX(ZPD,0,$B$8),J$18,Zepto_Data!$A$2:$A$3732,$B$11,Zepto_Data!$L$2:$L$3732,$B$12,Zepto_Data!$K$2:$K$3732,$B$13,Zepto_Data!$M$2:$M$3732,$B$14),IF($B$6="Sum",SUMIFS(INDEX(ZPD,0,$B$5),INDEX(ZPD,0,$B$3),$B24,INDEX(ZPD,0,$B$8),J$18,Zepto_Data!$A$2:$A$3732,$B$11,Zepto_Data!$L$2:$L$3732,$B$12,Zepto_Data!$K$2:$K$3732,$B$13,Zepto_Data!$M$2:$M$3732,$B$14),IFERROR(SUMIFS(INDEX(ZPD,0,$B$5),INDEX(ZPD,0,$B$3),$B24,INDEX(ZPD,0,$B$8),J$18,Zepto_Data!$A$2:$A$3732,$B$11,Zepto_Data!$L$2:$L$3732,$B$12,Zepto_Data!$K$2:$K$3732,$B$13,Zepto_Data!$M$2:$M$3732,$B$14)/COUNTIFS(INDEX(ZPD,0,$B$3),$B24,INDEX(ZPD,0,$B$8),J$18,Zepto_Data!$A$2:$A$3732,$B$11,Zepto_Data!$L$2:$L$3732,$B$12,Zepto_Data!$K$2:$K$3732,$B$13,Zepto_Data!$M$2:$M$3732,$B$14),0))))
A25: 6 | B25: =IF(INDEX(ZP_Lists!$L$2:$Q$21,A25,$B$2)="","",INDEX(ZP_Lists!$L$2:$Q$21,A25,$B$2)) -> Fruits & Vegetables | C25: =IF(B25="","",IF($B$6="Count",COUNTIFS(INDEX(ZPD,0,$B$3),B25,Zepto_Data!$A$2:$A$3732,$B$11,Zepto_Data!$L$2:$L$3732,$B$12,Zepto_Data!$K$2:$K$3732,$B$13,Zepto_Data!$M$2:$M$3732,$B$14),IF($B$6="Sum",SUMIFS(INDEX(ZPD,0,$B$5),INDEX(ZPD,0,$B$3),B25,Zepto_Data!$A$2:$A$3732,$B$11,Zepto_Data!$L$2:$L$3732,$B$12,Zepto_Data!$K$2:$K$3732,$B$13,Zepto_Data!$M$2:$M$3732,$B$14),IFERROR(SUMIFS(INDEX(ZPD,0,$B$5),INDEX(ZPD,0,$B$3),B25,Zepto_Data!$A$2:$A$3732,$B$11,Zepto_Data!$L$2:$L$3732,$B$12,Zepto_Data!$K$2:$K$3732,$B$13,Zepto_Data!$M$2:$M$3732,$B$14)/COUNTIFS(INDEX(ZPD,0,$B$3),B25,Zepto_Data!$A$2:$A$3732,$B$11,Zepto_Data!$L$2:$L$3732,$B$12,Zepto_Data!$K$2:$K$3732,$B$13,Zepto_Data!$M$2:$M$3732,$B$14),0)))) -> 10846 | D25: =IF(B25="","",IF($B$10="Natural order",A25,IF($B$10="Value: high to low",SUMPRODUCT(($B$20:$B$39<>"")*($C$20:$C$39>C25))+SUMPRODUCT(($B$20:B25<>"")*($C$20:C25=C25)),SUMPRODUCT(($B$20:$B$39<>"")*($C$20:$C$39<C25))+SUMPRODUCT(($B$20:B25<>"")*($C$20:C25=C25))))) -> 14 | F25: =IF(OR($B25="",F$18=""),"",IF($B$6="Count",COUNTIFS(INDEX(ZPD,0,$B$3),$B25,INDEX(ZPD,0,$B$8),F$18,Zepto_Data!$A$2:$A$3732,$B$11,Zepto_Data!$L$2:$L$3732,$B$12,Zepto_Data!$K$2:$K$3732,$B$13,Zepto_Data!$M$2:$M$3732,$B$14),IF($B$6="Sum",SUMIFS(INDEX(ZPD,0,$B$5),INDEX(ZPD,0,$B$3),$B25,INDEX(ZPD,0,$B$8),F$18,Zepto_Data!$A$2:$A$3732,$B$11,Zepto_Data!$L$2:$L$3732,$B$12,Zepto_Data!$K$2:$K$3732,$B$13,Zepto_Data!$M$2:$M$3732,$B$14),IFERROR(SUMIFS(INDEX(ZPD,0,$B$5),INDEX(ZPD,0,$B$3),$B25,INDEX(ZPD,0,$B$8),F$18,Zepto_Data!$A$2:$A$3732,$B$11,Zepto_Data!$L$2:$L$3732,$B$12,Zepto_Data!$K$2:$K$3732,$B$13,Zepto_Data!$M$2:$M$3732,$B$14)/COUNTIFS(INDEX(ZPD,0,$B$3),$B25,INDEX(ZPD,0,$B$8),F$18,Zepto_Data!$A$2:$A$3732,$B$11,Zepto_Data!$L$2:$L$3732,$B$12,Zepto_Data!$K$2:$K$3732,$B$13,Zepto_Data!$M$2:$M$3732,$B$14),0)))) -> 10846 | G25: =IF(OR($B25="",G$18=""),"",IF($B$6="Count",COUNTIFS(INDEX(ZPD,0,$B$3),$B25,INDEX(ZPD,0,$B$8),G$18,Zepto_Data!$A$2:$A$3732,$B$11,Zepto_Data!$L$2:$L$3732,$B$12,Zepto_Data!$K$2:$K$3732,$B$13,Zepto_Data!$M$2:$M$3732,$B$14),IF($B$6="Sum",SUMIFS(INDEX(ZPD,0,$B$5),INDEX(ZPD,0,$B$3),$B25,INDEX(ZPD,0,$B$8),G$18,Zepto_Data!$A$2:$A$3732,$B$11,Zepto_Data!$L$2:$L$3732,$B$12,Zepto_Data!$K$2:$K$3732,$B$13,Zepto_Data!$M$2:$M$3732,$B$14),IFERROR(SUMIFS(INDEX(ZPD,0,$B$5),INDEX(ZPD,0,$B$3),$B25,INDEX(ZPD,0,$B$8),G$18,Zepto_Data!$A$2:$A$3732,$B$11,Zepto_Data!$L$2:$L$3732,$B$12,Zepto_Data!$K$2:$K$3732,$B$13,Zepto_Data!$M$2:$M$3732,$B$14)/COUNTIFS(INDEX(ZPD,0,$B$3),$B25,INDEX(ZPD,0,$B$8),G$18,Zepto_Data!$A$2:$A$3732,$B$11,Zepto_Data!$L$2:$L$3732,$B$12,Zepto_Data!$K$2:$K$3732,$B$13,Zepto_Data!$M$2:$M$3732,$B$14),0)))) | H25: =IF(OR($B25="",H$18=""),"",IF($B$6="Count",COUNTIFS(INDEX(ZPD,0,$B$3),$B25,INDEX(ZPD,0,$B$8),H$18,Zepto_Data!$A$2:$A$3732,$B$11,Zepto_Data!$L$2:$L$3732,$B$12,Zepto_Data!$K$2:$K$3732,$B$13,Zepto_Data!$M$2:$M$3732,$B$14),IF($B$6="Sum",SUMIFS(INDEX(ZPD,0,$B$5),INDEX(ZPD,0,$B$3),$B25,INDEX(ZPD,0,$B$8),H$18,Zepto_Data!$A$2:$A$3732,$B$11,Zepto_Data!$L$2:$L$3732,$B$12,Zepto_Data!$K$2:$K$3732,$B$13,Zepto_Data!$M$2:$M$3732,$B$14),IFERROR(SUMIFS(INDEX(ZPD,0,$B$5),INDEX(ZPD,0,$B$3),$B25,INDEX(ZPD,0,$B$8),H$18,Zepto_Data!$A$2:$A$3732,$B$11,Zepto_Data!$L$2:$L$3732,$B$12,Zepto_Data!$K$2:$K$3732,$B$13,Zepto_Data!$M$2:$M$3732,$B$14)/COUNTIFS(INDEX(ZPD,0,$B$3),$B25,INDEX(ZPD,0,$B$8),H$18,Zepto_Data!$A$2:$A$3732,$B$11,Zepto_Data!$L$2:$L$3732,$B$12,Zepto_Data!$K$2:$K$3732,$B$13,Zepto_Data!$M$2:$M$3732,$B$14),0)))) | I25: =IF(OR($B25="",I$18=""),"",IF($B$6="Count",COUNTIFS(INDEX(ZPD,0,$B$3),$B25,INDEX(ZPD,0,$B$8),I$18,Zepto_Data!$A$2:$A$3732,$B$11,Zepto_Data!$L$2:$L$3732,$B$12,Zepto_Data!$K$2:$K$3732,$B$13,Zepto_Data!$M$2:$M$3732,$B$14),IF($B$6="Sum",SUMIFS(INDEX(ZPD,0,$B$5),INDEX(ZPD,0,$B$3),$B25,INDEX(ZPD,0,$B$8),I$18,Zepto_Data!$A$2:$A$3732,$B$11,Zepto_Data!$L$2:$L$3732,$B$12,Zepto_Data!$K$2:$K$3732,$B$13,Zepto_Data!$M$2:$M$3732,$B$14),IFERROR(SUMIFS(INDEX(ZPD,0,$B$5),INDEX(ZPD,0,$B$3),$B25,INDEX(ZPD,0,$B$8),I$18,Zepto_Data!$A$2:$A$3732,$B$11,Zepto_Data!$L$2:$L$3732,$B$12,Zepto_Data!$K$2:$K$3732,$B$13,Zepto_Data!$M$2:$M$3732,$B$14)/COUNTIFS(INDEX(ZPD,0,$B$3),$B25,INDEX(ZPD,0,$B$8),I$18,Zepto_Data!$A$2:$A$3732,$B$11,Zepto_Data!$L$2:$L$3732,$B$12,Zepto_Data!$K$2:$K$3732,$B$13,Zepto_Data!$M$2:$M$3732,$B$14),0)))) | J25: =IF(OR($B25="",J$18=""),"",IF($B$6="Count",COUNTIFS(INDEX(ZPD,0,$B$3),$B25,INDEX(ZPD,0,$B$8),J$18,Zepto_Data!$A$2:$A$3732,$B$11,Zepto_Data!$L$2:$L$3732,$B$12,Zepto_Data!$K$2:$K$3732,$B$13,Zepto_Data!$M$2:$M$3732,$B$14),IF($B$6="Sum",SUMIFS(INDEX(ZPD,0,$B$5),INDEX(ZPD,0,$B$3),$B25,INDEX(ZPD,0,$B$8),J$18,Zepto_Data!$A$2:$A$3732,$B$11,Zepto_Data!$L$2:$L$3732,$B$12,Zepto_Data!$K$2:$K$3732,$B$13,Zepto_Data!$M$2:$M$3732,$B$14),IFERROR(SUMIFS(INDEX(ZPD,0,$B$5),INDEX(ZPD,0,$B$3),$B25,INDEX(ZPD,0,$B$8),J$18,Zepto_Data!$A$2:$A$3732,$B$11,Zepto_Data!$L$2:$L$3732,$B$12,Zepto_Data!$K$2:$K$3732,$B$13,Zepto_Data!$M$2:$M$3732,$B$14)/COUNTIFS(INDEX(ZPD,0,$B$3),$B25,INDEX(ZPD,0,$B$8),J$18,Zepto_Data!$A$2:$A$3732,$B$11,Zepto_Data!$L$2:$L$3732,$B$12,Zepto_Data!$K$2:$K$3732,$B$13,Zepto_Data!$M$2:$M$3732,$B$14),0))))
A26: 7 | B26: =IF(INDEX(ZP_Lists!$L$2:$Q$21,A26,$B$2)="","",INDEX(ZP_Lists!$L$2:$Q$21,A26,$B$2)) -> Health & Hygiene | C26: =IF(B26="","",IF($B$6="Count",COUNTIFS(INDEX(ZPD,0,$B$3),B26,Zepto_Data!$A$2:$A$3732,$B$11,Zepto_Data!$L$2:$L$3732,$B$12,Zepto_Data!$K$2:$K$3732,$B$13,Zepto_Data!$M$2:$M$3732,$B$14),IF($B$6="Sum",SUMIFS(INDEX(ZPD,0,$B$5),INDEX(ZPD,0,$B$3),B26,Zepto_Data!$A$2:$A$3732,$B$11,Zepto_Data!$L$2:$L$3732,$B$12,Zepto_Data!$K$2:$K$3732,$B$13,Zepto_Data!$M$2:$M$3732,$B$14),IFERROR(SUMIFS(INDEX(ZPD,0,$B$5),INDEX(ZPD,0,$B$3),B26,Zepto_Data!$A$2:$A$3732,$B$11,Zepto_Data!$L$2:$L$3732,$B$12,Zepto_Data!$K$2:$K$3732,$B$13,Zepto_Data!$M$2:$M$3732,$B$14)/COUNTIFS(INDEX(ZPD,0,$B$3),B26,Zepto_Data!$A$2:$A$3732,$B$11,Zepto_Data!$L$2:$L$3732,$B$12,Zepto_Data!$K$2:$K$3732,$B$13,Zepto_Data!$M$2:$M$3732,$B$14),0)))) -> 64180 | D26: =IF(B26="","",IF($B$10="Natural order",A26,IF($B$10="Value: high to low",SUMPRODUCT(($B$20:$B$39<>"")*($C$20:$C$39>C26))+SUMPRODUCT(($B$20:B26<>"")*($C$20:C26=C26)),SUMPRODUCT(($B$20:$B$39<>"")*($C$20:$C$39<C26))+SUMPRODUCT(($B$20:B26<>"")*($C$20:C26=C26))))) -> 9 | F26: =IF(OR($B26="",F$18=""),"",IF($B$6="Count",COUNTIFS(INDEX(ZPD,0,$B$3),$B26,INDEX(ZPD,0,$B$8),F$18,Zepto_Data!$A$2:$A$3732,$B$11,Zepto_Data!$L$2:$L$3732,$B$12,Zepto_Data!$K$2:$K$3732,$B$13,Zepto_Data!$M$2:$M$3732,$B$14),IF($B$6="Sum",SUMIFS(INDEX(ZPD,0,$B$5),INDEX(ZPD,0,$B$3),$B26,INDEX(ZPD,0,$B$8),F$18,Zepto_Data!$A$2:$A$3732,$B$11,Zepto_Data!$L$2:$L$3732,$B$12,Zepto_Data!$K$2:$K$3732,$B$13,Zepto_Data!$M$2:$M$3732,$B$14),IFERROR(SUMIFS(INDEX(ZPD,0,$B$5),INDEX(ZPD,0,$B$3),$B26,INDEX(ZPD,0,$B$8),F$18,Zepto_Data!$A$2:$A$3732,$B$11,Zepto_Data!$L$2:$L$3732,$B$12,Zepto_Data!$K$2:$K$3732,$B$13,Zepto_Data!$M$2:$M$3732,$B$14)/COUNTIFS(INDEX(ZPD,0,$B$3),$B26,INDEX(ZPD,0,$B$8),F$18,Zepto_Data!$A$2:$A$3732,$B$11,Zepto_Data!$L$2:$L$3732,$B$12,Zepto_Data!$K$2:$K$3732,$B$13,Zepto_Data!$M$2:$M$3732,$B$14),0)))) -> 64180 | G26: =IF(OR($B26="",G$18=""),"",IF($B$6="Count",COUNTIFS(INDEX(ZPD,0,$B$3),$B26,INDEX(ZPD,0,$B$8),G$18,Zepto_Data!$A$2:$A$3732,$B$11,Zepto_Data!$L$2:$L$3732,$B$12,Zepto_Data!$K$2:$K$3732,$B$13,Zepto_Data!$M$2:$M$3732,$B$14),IF($B$6="Sum",SUMIFS(INDEX(ZPD,0,$B$5),INDEX(ZPD,0,$B$3),$B26,INDEX(ZPD,0,$B$8),G$18,Zepto_Data!$A$2:$A$3732,$B$11,Zepto_Data!$L$2:$L$3732,$B$12,Zepto_Data!$K$2:$K$3732,$B$13,Zepto_Data!$M$2:$M$3732,$B$14),IFERROR(SUMIFS(INDEX(ZPD,0,$B$5),INDEX(ZPD,0,$B$3),$B26,INDEX(ZPD,0,$B$8),G$18,Zepto_Data!$A$2:$A$3732,$B$11,Zepto_Data!$L$2:$L$3732,$B$12,Zepto_Data!$K$2:$K$3732,$B$13,Zepto_Data!$M$2:$M$3732,$B$14)/COUNTIFS(INDEX(ZPD,0,$B$3),$B26,INDEX(ZPD,0,$B$8),G$18,Zepto_Data!$A$2:$A$3732,$B$11,Zepto_Data!$L$2:$L$3732,$B$12,Zepto_Data!$K$2:$K$3732,$B$13,Zepto_Data!$M$2:$M$3732,$B$14),0)))) | H26: =IF(OR($B26="",H$18=""),"",IF($B$6="Count",COUNTIFS(INDEX(ZPD,0,$B$3),$B26,INDEX(ZPD,0,$B$8),H$18,Zepto_Data!$A$2:$A$3732,$B$11,Zepto_Data!$L$2:$L$3732,$B$12,Zepto_Data!$K$2:$K$3732,$B$13,Zepto_Data!$M$2:$M$3732,$B$14),IF($B$6="Sum",SUMIFS(INDEX(ZPD,0,$B$5),INDEX(ZPD,0,$B$3),$B26,INDEX(ZPD,0,$B$8),H$18,Zepto_Data!$A$2:$A$3732,$B$11,Zepto_Data!$L$2:$L$3732,$B$12,Zepto_Data!$K$2:$K$3732,$B$13,Zepto_Data!$M$2:$M$3732,$B$14),IFERROR(SUMIFS(INDEX(ZPD,0,$B$5),INDEX(ZPD,0,$B$3),$B26,INDEX(ZPD,0,$B$8),H$18,Zepto_Data!$A$2:$A$3732,$B$11,Zepto_Data!$L$2:$L$3732,$B$12,Zepto_Data!$K$2:$K$3732,$B$13,Zepto_Data!$M$2:$M$3732,$B$14)/COUNTIFS(INDEX(ZPD,0,$B$3),$B26,INDEX(ZPD,0,$B$8),H$18,Zepto_Data!$A$2:$A$3732,$B$11,Zepto_Data!$L$2:$L$3732,$B$12,Zepto_Data!$K$2:$K$3732,$B$13,Zepto_Data!$M$2:$M$3732,$B$14),0)))) | I26: =IF(OR($B26="",I$18=""),"",IF($B$6="Count",COUNTIFS(INDEX(ZPD,0,$B$3),$B26,INDEX(ZPD,0,$B$8),I$18,Zepto_Data!$A$2:$A$3732,$B$11,Zepto_Data!$L$2:$L$3732,$B$12,Zepto_Data!$K$2:$K$3732,$B$13,Zepto_Data!$M$2:$M$3732,$B$14),IF($B$6="Sum",SUMIFS(INDEX(ZPD,0,$B$5),INDEX(ZPD,0,$B$3),$B26,INDEX(ZPD,0,$B$8),I$18,Zepto_Data!$A$2:$A$3732,$B$11,Zepto_Data!$L$2:$L$3732,$B$12,Zepto_Data!$K$2:$K$3732,$B$13,Zepto_Data!$M$2:$M$3732,$B$14),IFERROR(SUMIFS(INDEX(ZPD,0,$B$5),INDEX(ZPD,0,$B$3),$B26,INDEX(ZPD,0,$B$8),I$18,Zepto_Data!$A$2:$A$3732,$B$11,Zepto_Data!$L$2:$L$3732,$B$12,Zepto_Data!$K$2:$K$3732,$B$13,Zepto_Data!$M$2:$M$3732,$B$14)/COUNTIFS(INDEX(ZPD,0,$B$3),$B26,INDEX(ZPD,0,$B$8),I$18,Zepto_Data!$A$2:$A$3732,$B$11,Zepto_Data!$L$2:$L$3732,$B$12,Zepto_Data!$K$2:$K$3732,$B$13,Zepto_Data!$M$2:$M$3732,$B$14),0)))) | J26: =IF(OR($B26="",J$18=""),"",IF($B$6="Count",COUNTIFS(INDEX(ZPD,0,$B$3),$B26,INDEX(ZPD,0,$B$8),J$18,Zepto_Data!$A$2:$A$3732,$B$11,Zepto_Data!$L$2:$L$3732,$B$12,Zepto_Data!$K$2:$K$3732,$B$13,Zepto_Data!$M$2:$M$3732,$B$14),IF($B$6="Sum",SUMIFS(INDEX(ZPD,0,$B$5),INDEX(ZPD,0,$B$3),$B26,INDEX(ZPD,0,$B$8),J$18,Zepto_Data!$A$2:$A$3732,$B$11,Zepto_Data!$L$2:$L$3732,$B$12,Zepto_Data!$K$2:$K$3732,$B$13,Zepto_Data!$M$2:$M$3732,$B$14),IFERROR(SUMIFS(INDEX(ZPD,0,$B$5),INDEX(ZPD,0,$B$3),$B26,INDEX(ZPD,0,$B$8),J$18,Zepto_Data!$A$2:$A$3732,$B$11,Zepto_Data!$L$2:$L$3732,$B$12,Zepto_Data!$K$2:$K$3732,$B$13,Zepto_Data!$M$2:$M$3732,$B$14)/COUNTIFS(INDEX(ZPD,0,$B$3),$B26,INDEX(ZPD,0,$B$8),J$18,Zepto_Data!$A$2:$A$3732,$B$11,Zepto_Data!$L$2:$L$3732,$B$12,Zepto_Data!$K$2:$K$3732,$B$13,Zepto_Data!$M$2:$M$3732,$B$14),0))))
A27: 8 | B27: =IF(INDEX(ZP_Lists!$L$2:$Q$21,A27,$B$2)="","",INDEX(ZP_Lists!$L$2:$Q$21,A27,$B$2)) -> Home & Cleaning | C27: =IF(B27="","",IF($B$6="Count",COUNTIFS(INDEX(ZPD,0,$B$3),B27,Zepto_Data!$A$2:$A$3732,$B$11,Zepto_Data!$L$2:$L$3732,$B$12,Zepto_Data!$K$2:$K$3732,$B$13,Zepto_Data!$M$2:$M$3732,$B$14),IF($B$6="Sum",SUMIFS(INDEX(ZPD,0,$B$5),INDEX(ZPD,0,$B$3),B27,Zepto_Data!$A$2:$A$3732,$B$11,Zepto_Data!$L$2:$L$3732,$B$12,Zepto_Data!$K$2:$K$3732,$B$13,Zepto_Data!$M$2:$M$3732,$B$14),IFERROR(SUMIFS(INDEX(ZPD,0,$B$5),INDEX(ZPD,0,$B$3),B27,Zepto_Data!$A$2:$A$3732,$B$11,Zepto_Data!$L$2:$L$3732,$B$12,Zepto_Data!$K$2:$K$3732,$B$13,Zepto_Data!$M$2:$M$3732,$B$14)/COUNTIFS(INDEX(ZPD,0,$B$3),B27,Zepto_Data!$A$2:$A$3732,$B$11,Zepto_Data!$L$2:$L$3732,$B$12,Zepto_Data!$K$2:$K$3732,$B$13,Zepto_Data!$M$2:$M$3732,$B$14),0)))) -> 122661 | D27: =IF(B27="","",IF($B$10="Natural order",A27,IF($B$10="Value: high to low",SUMPRODUCT(($B$20:$B$39<>"")*($C$20:$C$39>C27))+SUMPRODUCT(($B$20:B27<>"")*($C$20:C27=C27)),SUMPRODUCT(($B$20:$B$39<>"")*($C$20:$C$39<C27))+SUMPRODUCT(($B$20:B27<>"")*($C$20:C27=C27))))) -> 8 | F27: =IF(OR($B27="",F$18=""),"",IF($B$6="Count",COUNTIFS(INDEX(ZPD,0,$B$3),$B27,INDEX(ZPD,0,$B$8),F$18,Zepto_Data!$A$2:$A$3732,$B$11,Zepto_Data!$L$2:$L$3732,$B$12,Zepto_Data!$K$2:$K$3732,$B$13,Zepto_Data!$M$2:$M$3732,$B$14),IF($B$6="Sum",SUMIFS(INDEX(ZPD,0,$B$5),INDEX(ZPD,0,$B$3),$B27,INDEX(ZPD,0,$B$8),F$18,Zepto_Data!$A$2:$A$3732,$B$11,Zepto_Data!$L$2:$L$3732,$B$12,Zepto_Data!$K$2:$K$3732,$B$13,Zepto_Data!$M$2:$M$3732,$B$14),IFERROR(SUMIFS(INDEX(ZPD,0,$B$5),INDEX(ZPD,0,$B$3),$B27,INDEX(ZPD,0,$B$8),F$18,Zepto_Data!$A$2:$A$3732,$B$11,Zepto_Data!$L$2:$L$3732,$B$12,Zepto_Data!$K$2:$K$3732,$B$13,Zepto_Data!$M$2:$M$3732,$B$14)/COUNTIFS(INDEX(ZPD,0,$B$3),$B27,INDEX(ZPD,0,$B$8),F$18,Zepto_Data!$A$2:$A$3732,$B$11,Zepto_Data!$L$2:$L$3732,$B$12,Zepto_Data!$K$2:$K$3732,$B$13,Zepto_Data!$M$2:$M$3732,$B$14),0)))) -> 122661 | G27: =IF(OR($B27="",G$18=""),"",IF($B$6="Count",COUNTIFS(INDEX(ZPD,0,$B$3),$B27,INDEX(ZPD,0,$B$8),G$18,Zepto_Data!$A$2:$A$3732,$B$11,Zepto_Data!$L$2:$L$3732,$B$12,Zepto_Data!$K$2:$K$3732,$B$13,Zepto_Data!$M$2:$M$3732,$B$14),IF($B$6="Sum",SUMIFS(INDEX(ZPD,0,$B$5),INDEX(ZPD,0,$B$3),$B27,INDEX(ZPD,0,$B$8),G$18,Zepto_Data!$A$2:$A$3732,$B$11,Zepto_Data!$L$2:$L$3732,$B$12,Zepto_Data!$K$2:$K$3732,$B$13,Zepto_Data!$M$2:$M$3732,$B$14),IFERROR(SUMIFS(INDEX(ZPD,0,$B$5),INDEX(ZPD,0,$B$3),$B27,INDEX(ZPD,0,$B$8),G$18,Zepto_Data!$A$2:$A$3732,$B$11,Zepto_Data!$L$2:$L$3732,$B$12,Zepto_Data!$K$2:$K$3732,$B$13,Zepto_Data!$M$2:$M$3732,$B$14)/COUNTIFS(INDEX(ZPD,0,$B$3),$B27,INDEX(ZPD,0,$B$8),G$18,Zepto_Data!$A$2:$A$3732,$B$11,Zepto_Data!$L$2:$L$3732,$B$12,Zepto_Data!$K$2:$K$3732,$B$13,Zepto_Data!$M$2:$M$3732,$B$14),0)))) | H27: =IF(OR($B27="",H$18=""),"",IF($B$6="Count",COUNTIFS(INDEX(ZPD,0,$B$3),$B27,INDEX(ZPD,0,$B$8),H$18,Zepto_Data!$A$2:$A$3732,$B$11,Zepto_Data!$L$2:$L$3732,$B$12,Zepto_Data!$K$2:$K$3732,$B$13,Zepto_Data!$M$2:$M$3732,$B$14),IF($B$6="Sum",SUMIFS(INDEX(ZPD,0,$B$5),INDEX(ZPD,0,$B$3),$B27,INDEX(ZPD,0,$B$8),H$18,Zepto_Data!$A$2:$A$3732,$B$11,Zepto_Data!$L$2:$L$3732,$B$12,Zepto_Data!$K$2:$K$3732,$B$13,Zepto_Data!$M$2:$M$3732,$B$14),IFERROR(SUMIFS(INDEX(ZPD,0,$B$5),INDEX(ZPD,0,$B$3),$B27,INDEX(ZPD,0,$B$8),H$18,Zepto_Data!$A$2:$A$3732,$B$11,Zepto_Data!$L$2:$L$3732,$B$12,Zepto_Data!$K$2:$K$3732,$B$13,Zepto_Data!$M$2:$M$3732,$B$14)/COUNTIFS(INDEX(ZPD,0,$B$3),$B27,INDEX(ZPD,0,$B$8),H$18,Zepto_Data!$A$2:$A$3732,$B$11,Zepto_Data!$L$2:$L$3732,$B$12,Zepto_Data!$K$2:$K$3732,$B$13,Zepto_Data!$M$2:$M$3732,$B$14),0)))) | I27: =IF(OR($B27="",I$18=""),"",IF($B$6="Count",COUNTIFS(INDEX(ZPD,0,$B$3),$B27,INDEX(ZPD,0,$B$8),I$18,Zepto_Data!$A$2:$A$3732,$B$11,Zepto_Data!$L$2:$L$3732,$B$12,Zepto_Data!$K$2:$K$3732,$B$13,Zepto_Data!$M$2:$M$3732,$B$14),IF($B$6="Sum",SUMIFS(INDEX(ZPD,0,$B$5),INDEX(ZPD,0,$B$3),$B27,INDEX(ZPD,0,$B$8),I$18,Zepto_Data!$A$2:$A$3732,$B$11,Zepto_Data!$L$2:$L$3732,$B$12,Zepto_Data!$K$2:$K$3732,$B$13,Zepto_Data!$M$2:$M$3732,$B$14),IFERROR(SUMIFS(INDEX(ZPD,0,$B$5),INDEX(ZPD,0,$B$3),$B27,INDEX(ZPD,0,$B$8),I$18,Zepto_Data!$A$2:$A$3732,$B$11,Zepto_Data!$L$2:$L$3732,$B$12,Zepto_Data!$K$2:$K$3732,$B$13,Zepto_Data!$M$2:$M$3732,$B$14)/COUNTIFS(INDEX(ZPD,0,$B$3),$B27,INDEX(ZPD,0,$B$8),I$18,Zepto_Data!$A$2:$A$3732,$B$11,Zepto_Data!$L$2:$L$3732,$B$12,Zepto_Data!$K$2:$K$3732,$B$13,Zepto_Data!$M$2:$M$3732,$B$14),0)))) | J27: =IF(OR($B27="",J$18=""),"",IF($B$6="Count",COUNTIFS(INDEX(ZPD,0,$B$3),$B27,INDEX(ZPD,0,$B$8),J$18,Zepto_Data!$A$2:$A$3732,$B$11,Zepto_Data!$L$2:$L$3732,$B$12,Zepto_Data!$K$2:$K$3732,$B$13,Zepto_Data!$M$2:$M$3732,$B$14),IF($B$6="Sum",SUMIFS(INDEX(ZPD,0,$B$5),INDEX(ZPD,0,$B$3),$B27,INDEX(ZPD,0,$B$8),J$18,Zepto_Data!$A$2:$A$3732,$B$11,Zepto_Data!$L$2:$L$3732,$B$12,Zepto_Data!$K$2:$K$3732,$B$13,Zepto_Data!$M$2:$M$3732,$B$14),IFERROR(SUMIFS(INDEX(ZPD,0,$B$5),INDEX(ZPD,0,$B$3),$B27,INDEX(ZPD,0,$B$8),J$18,Zepto_Data!$A$2:$A$3732,$B$11,Zepto_Data!$L$2:$L$3732,$B$12,Zepto_Data!$K$2:$K$3732,$B$13,Zepto_Data!$M$2:$M$3732,$B$14)/COUNTIFS(INDEX(ZPD,0,$B$3),$B27,INDEX(ZPD,0,$B$8),J$18,Zepto_Data!$A$2:$A$3732,$B$11,Zepto_Data!$L$2:$L$3732,$B$12,Zepto_Data!$K$2:$K$3732,$B$13,Zepto_Data!$M$2:$M$3732,$B$14),0))))
A28: 9 | B28: =IF(INDEX(ZP_Lists!$L$2:$Q$21,A28,$B$2)="","",INDEX(ZP_Lists!$L$2:$Q$21,A28,$B$2)) -> Ice Cream & Desserts | C28: =IF(B28="","",IF($B$6="Count",COUNTIFS(INDEX(ZPD,0,$B$3),B28,Zepto_Data!$A$2:$A$3732,$B$11,Zepto_Data!$L$2:$L$3732,$B$12,Zepto_Data!$K$2:$K$3732,$B$13,Zepto_Data!$M$2:$M$3732,$B$14),IF($B$6="Sum",SUMIFS(INDEX(ZPD,0,$B$5),INDEX(ZPD,0,$B$3),B28,Zepto_Data!$A$2:$A$3732,$B$11,Zepto_Data!$L$2:$L$3732,$B$12,Zepto_Data!$K$2:$K$3732,$B$13,Zepto_Data!$M$2:$M$3732,$B$14),IFERROR(SUMIFS(INDEX(ZPD,0,$B$5),INDEX(ZPD,0,$B$3),B28,Zepto_Data!$A$2:$A$3732,$B$11,Zepto_Data!$L$2:$L$3732,$B$12,Zepto_Data!$K$2:$K$3732,$B$13,Zepto_Data!$M$2:$M$3732,$B$14)/COUNTIFS(INDEX(ZPD,0,$B$3),B28,Zepto_Data!$A$2:$A$3732,$B$11,Zepto_Data!$L$2:$L$3732,$B$12,Zepto_Data!$K$2:$K$3732,$B$13,Zepto_Data!$M$2:$M$3732,$B$14),0)))) -> 224385 | D28: =IF(B28="","",IF($B$10="Natural order",A28,IF($B$10="Value: high to low",SUMPRODUCT(($B$20:$B$39<>"")*($C$20:$C$39>C28))+SUMPRODUCT(($B$20:B28<>"")*($C$20:C28=C28)),SUMPRODUCT(($B$20:$B$39<>"")*($C$20:$C$39<C28))+SUMPRODUCT(($B$20:B28<>"")*($C$20:C28=C28))))) -> 6 | F28: =IF(OR($B28="",F$18=""),"",IF($B$6="Count",COUNTIFS(INDEX(ZPD,0,$B$3),$B28,INDEX(ZPD,0,$B$8),F$18,Zepto_Data!$A$2:$A$3732,$B$11,Zepto_Data!$L$2:$L$3732,$B$12,Zepto_Data!$K$2:$K$3732,$B$13,Zepto_Data!$M$2:$M$3732,$B$14),IF($B$6="Sum",SUMIFS(INDEX(ZPD,0,$B$5),INDEX(ZPD,0,$B$3),$B28,INDEX(ZPD,0,$B$8),F$18,Zepto_Data!$A$2:$A$3732,$B$11,Zepto_Data!$L$2:$L$3732,$B$12,Zepto_Data!$K$2:$K$3732,$B$13,Zepto_Data!$M$2:$M$3732,$B$14),IFERROR(SUMIFS(INDEX(ZPD,0,$B$5),INDEX(ZPD,0,$B$3),$B28,INDEX(ZPD,0,$B$8),F$18,Zepto_Data!$A$2:$A$3732,$B$11,Zepto_Data!$L$2:$L$3732,$B$12,Zepto_Data!$K$2:$K$3732,$B$13,Zepto_Data!$M$2:$M$3732,$B$14)/COUNTIFS(INDEX(ZPD,0,$B$3),$B28,INDEX(ZPD,0,$B$8),F$18,Zepto_Data!$A$2:$A$3732,$B$11,Zepto_Data!$L$2:$L$3732,$B$12,Zepto_Data!$K$2:$K$3732,$B$13,Zepto_Data!$M$2:$M$3732,$B$14),0)))) -> 224385 | G28: =IF(OR($B28="",G$18=""),"",IF($B$6="Count",COUNTIFS(INDEX(ZPD,0,$B$3),$B28,INDEX(ZPD,0,$B$8),G$18,Zepto_Data!$A$2:$A$3732,$B$11,Zepto_Data!$L$2:$L$3732,$B$12,Zepto_Data!$K$2:$K$3732,$B$13,Zepto_Data!$M$2:$M$3732,$B$14),IF($B$6="Sum",SUMIFS(INDEX(ZPD,0,$B$5),INDEX(ZPD,0,$B$3),$B28,INDEX(ZPD,0,$B$8),G$18,Zepto_Data!$A$2:$A$3732,$B$11,Zepto_Data!$L$2:$L$3732,$B$12,Zepto_Data!$K$2:$K$3732,$B$13,Zepto_Data!$M$2:$M$3732,$B$14),IFERROR(SUMIFS(INDEX(ZPD,0,$B$5),INDEX(ZPD,0,$B$3),$B28,INDEX(ZPD,0,$B$8),G$18,Zepto_Data!$A$2:$A$3732,$B$11,Zepto_Data!$L$2:$L$3732,$B$12,Zepto_Data!$K$2:$K$3732,$B$13,Zepto_Data!$M$2:$M$3732,$B$14)/COUNTIFS(INDEX(ZPD,0,$B$3),$B28,INDEX(ZPD,0,$B$8),G$18,Zepto_Data!$A$2:$A$3732,$B$11,Zepto_Data!$L$2:$L$3732,$B$12,Zepto_Data!$K$2:$K$3732,$B$13,Zepto_Data!$M$2:$M$3732,$B$14),0)))) | H28: =IF(OR($B28="",H$18=""),"",IF($B$6="Count",COUNTIFS(INDEX(ZPD,0,$B$3),$B28,INDEX(ZPD,0,$B$8),H$18,Zepto_Data!$A$2:$A$3732,$B$11,Zepto_Data!$L$2:$L$3732,$B$12,Zepto_Data!$K$2:$K$3732,$B$13,Zepto_Data!$M$2:$M$3732,$B$14),IF($B$6="Sum",SUMIFS(INDEX(ZPD,0,$B$5),INDEX(ZPD,0,$B$3),$B28,INDEX(ZPD,0,$B$8),H$18,Zepto_Data!$A$2:$A$3732,$B$11,Zepto_Data!$L$2:$L$3732,$B$12,Zepto_Data!$K$2:$K$3732,$B$13,Zepto_Data!$M$2:$M$3732,$B$14),IFERROR(SUMIFS(INDEX(ZPD,0,$B$5),INDEX(ZPD,0,$B$3),$B28,INDEX(ZPD,0,$B$8),H$18,Zepto_Data!$A$2:$A$3732,$B$11,Zepto_Data!$L$2:$L$3732,$B$12,Zepto_Data!$K$2:$K$3732,$B$13,Zepto_Data!$M$2:$M$3732,$B$14)/COUNTIFS(INDEX(ZPD,0,$B$3),$B28,INDEX(ZPD,0,$B$8),H$18,Zepto_Data!$A$2:$A$3732,$B$11,Zepto_Data!$L$2:$L$3732,$B$12,Zepto_Data!$K$2:$K$3732,$B$13,Zepto_Data!$M$2:$M$3732,$B$14),0)))) | I28: =IF(OR($B28="",I$18=""),"",IF($B$6="Count",COUNTIFS(INDEX(ZPD,0,$B$3),$B28,INDEX(ZPD,0,$B$8),I$18,Zepto_Data!$A$2:$A$3732,$B$11,Zepto_Data!$L$2:$L$3732,$B$12,Zepto_Data!$K$2:$K$3732,$B$13,Zepto_Data!$M$2:$M$3732,$B$14),IF($B$6="Sum",SUMIFS(INDEX(ZPD,0,$B$5),INDEX(ZPD,0,$B$3),$B28,INDEX(ZPD,0,$B$8),I$18,Zepto_Data!$A$2:$A$3732,$B$11,Zepto_Data!$L$2:$L$3732,$B$12,Zepto_Data!$K$2:$K$3732,$B$13,Zepto_Data!$M$2:$M$3732,$B$14),IFERROR(SUMIFS(INDEX(ZPD,0,$B$5),INDEX(ZPD,0,$B$3),$B28,INDEX(ZPD,0,$B$8),I$18,Zepto_Data!$A$2:$A$3732,$B$11,Zepto_Data!$L$2:$L$3732,$B$12,Zepto_Data!$K$2:$K$3732,$B$13,Zepto_Data!$M$2:$M$3732,$B$14)/COUNTIFS(INDEX(ZPD,0,$B$3),$B28,INDEX(ZPD,0,$B$8),I$18,Zepto_Data!$A$2:$A$3732,$B$11,Zepto_Data!$L$2:$L$3732,$B$12,Zepto_Data!$K$2:$K$3732,$B$13,Zepto_Data!$M$2:$M$3732,$B$14),0)))) | J28: =IF(OR($B28="",J$18=""),"",IF($B$6="Count",COUNTIFS(INDEX(ZPD,0,$B$3),$B28,INDEX(ZPD,0,$B$8),J$18,Zepto_Data!$A$2:$A$3732,$B$11,Zepto_Data!$L$2:$L$3732,$B$12,Zepto_Data!$K$2:$K$3732,$B$13,Zepto_Data!$M$2:$M$3732,$B$14),IF($B$6="Sum",SUMIFS(INDEX(ZPD,0,$B$5),INDEX(ZPD,0,$B$3),$B28,INDEX(ZPD,0,$B$8),J$18,Zepto_Data!$A$2:$A$3732,$B$11,Zepto_Data!$L$2:$L$3732,$B$12,Zepto_Data!$K$2:$K$3732,$B$13,Zepto_Data!$M$2:$M$3732,$B$14),IFERROR(SUMIFS(INDEX(ZPD,0,$B$5),INDEX(ZPD,0,$B$3),$B28,INDEX(ZPD,0,$B$8),J$18,Zepto_Data!$A$2:$A$3732,$B$11,Zepto_Data!$L$2:$L$3732,$B$12,Zepto_Data!$K$2:$K$3732,$B$13,Zepto_Data!$M$2:$M$3732,$B$14)/COUNTIFS(INDEX(ZPD,0,$B$3),$B28,INDEX(ZPD,0,$B$8),J$18,Zepto_Data!$A$2:$A$3732,$B$11,Zepto_Data!$L$2:$L$3732,$B$12,Zepto_Data!$K$2:$K$3732,$B$13,Zepto_Data!$M$2:$M$3732,$B$14),0))))
A29: 10 | B29: =IF(INDEX(ZP_Lists!$L$2:$Q$21,A29,$B$2)="","",INDEX(ZP_Lists!$L$2:$Q$21,A29,$B$2)) -> Meats, Fish & Eggs | C29: =IF(B29="","",IF($B$6="Count",COUNTIFS(INDEX(ZPD,0,$B$3),B29,Zepto_Data!$A$2:$A$3732,$B$11,Zepto_Data!$L$2:$L$3732,$B$12,Zepto_Data!$K$2:$K$3732,$B$13,Zepto_Data!$M$2:$M$3732,$B$14),IF($B$6="Sum",SUMIFS(INDEX(ZPD,0,$B$5),INDEX(ZPD,0,$B$3),B29,Zepto_Data!$A$2:$A$3732,$B$11,Zepto_Data!$L$2:$L$3732,$B$12,Zepto_Data!$K$2:$K$3732,$B$13,Zepto_Data!$M$2:$M$3732,$B$14),IFERROR(SUMIFS(INDEX(ZPD,0,$B$5),INDEX(ZPD,0,$B$3),B29,Zepto_Data!$A$2:$A$3732,$B$11,Zepto_Data!$L$2:$L$3732,$B$12,Zepto_Data!$K$2:$K$3732,$B$13,Zepto_Data!$M$2:$M$3732,$B$14)/COUNTIFS(INDEX(ZPD,0,$B$3),B29,Zepto_Data!$A$2:$A$3732,$B$11,Zepto_Data!$L$2:$L$3732,$B$12,Zepto_Data!$K$2:$K$3732,$B$13,Zepto_Data!$M$2:$M$3732,$B$14),0)))) -> 20693 | D29: =IF(B29="","",IF($B$10="Natural order",A29,IF($B$10="Value: high to low",SUMPRODUCT(($B$20:$B$39<>"")*($C$20:$C$39>C29))+SUMPRODUCT(($B$20:B29<>"")*($C$20:C29=C29)),SUMPRODUCT(($B$20:$B$39<>"")*($C$20:$C$39<C29))+SUMPRODUCT(($B$20:B29<>"")*($C$20:C29=C29))))) -> 13 | F29: =IF(OR($B29="",F$18=""),"",IF($B$6="Count",COUNTIFS(INDEX(ZPD,0,$B$3),$B29,INDEX(ZPD,0,$B$8),F$18,Zepto_Data!$A$2:$A$3732,$B$11,Zepto_Data!$L$2:$L$3732,$B$12,Zepto_Data!$K$2:$K$3732,$B$13,Zepto_Data!$M$2:$M$3732,$B$14),IF($B$6="Sum",SUMIFS(INDEX(ZPD,0,$B$5),INDEX(ZPD,0,$B$3),$B29,INDEX(ZPD,0,$B$8),F$18,Zepto_Data!$A$2:$A$3732,$B$11,Zepto_Data!$L$2:$L$3732,$B$12,Zepto_Data!$K$2:$K$3732,$B$13,Zepto_Data!$M$2:$M$3732,$B$14),IFERROR(SUMIFS(INDEX(ZPD,0,$B$5),INDEX(ZPD,0,$B$3),$B29,INDEX(ZPD,0,$B$8),F$18,Zepto_Data!$A$2:$A$3732,$B$11,Zepto_Data!$L$2:$L$3732,$B$12,Zepto_Data!$K$2:$K$3732,$B$13,Zepto_Data!$M$2:$M$3732,$B$14)/COUNTIFS(INDEX(ZPD,0,$B$3),$B29,INDEX(ZPD,0,$B$8),F$18,Zepto_Data!$A$2:$A$3732,$B$11,Zepto_Data!$L$2:$L$3732,$B$12,Zepto_Data!$K$2:$K$3732,$B$13,Zepto_Data!$M$2:$M$3732,$B$14),0)))) -> 20693 | G29: =IF(OR($B29="",G$18=""),"",IF($B$6="Count",COUNTIFS(INDEX(ZPD,0,$B$3),$B29,INDEX(ZPD,0,$B$8),G$18,Zepto_Data!$A$2:$A$3732,$B$11,Zepto_Data!$L$2:$L$3732,$B$12,Zepto_Data!$K$2:$K$3732,$B$13,Zepto_Data!$M$2:$M$3732,$B$14),IF($B$6="Sum",SUMIFS(INDEX(ZPD,0,$B$5),INDEX(ZPD,0,$B$3),$B29,INDEX(ZPD,0,$B$8),G$18,Zepto_Data!$A$2:$A$3732,$B$11,Zepto_Data!$L$2:$L$3732,$B$12,Zepto_Data!$K$2:$K$3732,$B$13,Zepto_Data!$M$2:$M$3732,$B$14),IFERROR(SUMIFS(INDEX(ZPD,0,$B$5),INDEX(ZPD,0,$B$3),$B29,INDEX(ZPD,0,$B$8),G$18,Zepto_Data!$A$2:$A$3732,$B$11,Zepto_Data!$L$2:$L$3732,$B$12,Zepto_Data!$K$2:$K$3732,$B$13,Zepto_Data!$M$2:$M$3732,$B$14)/COUNTIFS(INDEX(ZPD,0,$B$3),$B29,INDEX(ZPD,0,$B$8),G$18,Zepto_Data!$A$2:$A$3732,$B$11,Zepto_Data!$L$2:$L$3732,$B$12,Zepto_Data!$K$2:$K$3732,$B$13,Zepto_Data!$M$2:$M$3732,$B$14),0)))) | H29: =IF(OR($B29="",H$18=""),"",IF($B$6="Count",COUNTIFS(INDEX(ZPD,0,$B$3),$B29,INDEX(ZPD,0,$B$8),H$18,Zepto_Data!$A$2:$A$3732,$B$11,Zepto_Data!$L$2:$L$3732,$B$12,Zepto_Data!$K$2:$K$3732,$B$13,Zepto_Data!$M$2:$M$3732,$B$14),IF($B$6="Sum",SUMIFS(INDEX(ZPD,0,$B$5),INDEX(ZPD,0,$B$3),$B29,INDEX(ZPD,0,$B$8),H$18,Zepto_Data!$A$2:$A$3732,$B$11,Zepto_Data!$L$2:$L$3732,$B$12,Zepto_Data!$K$2:$K$3732,$B$13,Zepto_Data!$M$2:$M$3732,$B$14),IFERROR(SUMIFS(INDEX(ZPD,0,$B$5),INDEX(ZPD,0,$B$3),$B29,INDEX(ZPD,0,$B$8),H$18,Zepto_Data!$A$2:$A$3732,$B$11,Zepto_Data!$L$2:$L$3732,$B$12,Zepto_Data!$K$2:$K$3732,$B$13,Zepto_Data!$M$2:$M$3732,$B$14)/COUNTIFS(INDEX(ZPD,0,$B$3),$B29,INDEX(ZPD,0,$B$8),H$18,Zepto_Data!$A$2:$A$3732,$B$11,Zepto_Data!$L$2:$L$3732,$B$12,Zepto_Data!$K$2:$K$3732,$B$13,Zepto_Data!$M$2:$M$3732,$B$14),0)))) | I29: =IF(OR($B29="",I$18=""),"",IF($B$6="Count",COUNTIFS(INDEX(ZPD,0,$B$3),$B29,INDEX(ZPD,0,$B$8),I$18,Zepto_Data!$A$2:$A$3732,$B$11,Zepto_Data!$L$2:$L$3732,$B$12,Zepto_Data!$K$2:$K$3732,$B$13,Zepto_Data!$M$2:$M$3732,$B$14),IF($B$6="Sum",SUMIFS(INDEX(ZPD,0,$B$5),INDEX(ZPD,0,$B$3),$B29,INDEX(ZPD,0,$B$8),I$18,Zepto_Data!$A$2:$A$3732,$B$11,Zepto_Data!$L$2:$L$3732,$B$12,Zepto_Data!$K$2:$K$3732,$B$13,Zepto_Data!$M$2:$M$3732,$B$14),IFERROR(SUMIFS(INDEX(ZPD,0,$B$5),INDEX(ZPD,0,$B$3),$B29,INDEX(ZPD,0,$B$8),I$18,Zepto_Data!$A$2:$A$3732,$B$11,Zepto_Data!$L$2:$L$3732,$B$12,Zepto_Data!$K$2:$K$3732,$B$13,Zepto_Data!$M$2:$M$3732,$B$14)/COUNTIFS(INDEX(ZPD,0,$B$3),$B29,INDEX(ZPD,0,$B$8),I$18,Zepto_Data!$A$2:$A$3732,$B$11,Zepto_Data!$L$2:$L$3732,$B$12,Zepto_Data!$K$2:$K$3732,$B$13,Zepto_Data!$M$2:$M$3732,$B$14),0)))) | J29: =IF(OR($B29="",J$18=""),"",IF($B$6="Count",COUNTIFS(INDEX(ZPD,0,$B$3),$B29,INDEX(ZPD,0,$B$8),J$18,Zepto_Data!$A$2:$A$3732,$B$11,Zepto_Data!$L$2:$L$3732,$B$12,Zepto_Data!$K$2:$K$3732,$B$13,Zepto_Data!$M$2:$M$3732,$B$14),IF($B$6="Sum",SUMIFS(INDEX(ZPD,0,$B$5),INDEX(ZPD,0,$B$3),$B29,INDEX(ZPD,0,$B$8),J$18,Zepto_Data!$A$2:$A$3732,$B$11,Zepto_Data!$L$2:$L$3732,$B$12,Zepto_Data!$K$2:$K$3732,$B$13,Zepto_Data!$M$2:$M$3732,$B$14),IFERROR(SUMIFS(INDEX(ZPD,0,$B$5),INDEX(ZPD,0,$B$3),$B29,INDEX(ZPD,0,$B$8),J$18,Zepto_Data!$A$2:$A$3732,$B$11,Zepto_Data!$L$2:$L$3732,$B$12,Zepto_Data!$K$2:$K$3732,$B$13,Zepto_Data!$M$2:$M$3732,$B$14)/COUNTIFS(INDEX(ZPD,0,$B$3),$B29,INDEX(ZPD,0,$B$8),J$18,Zepto_Data!$A$2:$A$3732,$B$11,Zepto_Data!$L$2:$L$3732,$B$12,Zepto_Data!$K$2:$K$3732,$B$13,Zepto_Data!$M$2:$M$3732,$B$14),0))))
